Workbook

Sheet Hoja2
A2: CANCHAS | B2: Jugadores inscritos
A3: 1 | B3: MAURICIO ALEJANDRO BAUTISTA | E3: 1
A4: 1 | B4: MARIANO GOMEZ VUILLEUMIER | E4: 1
A5: 1 | B5: NICOLAS MAXIMILIANO BRILL HERRERA | E5: 1
A6: 2 | B6: MARIANO NAVARRO LEAÑO | E6: 1
A7: 2 | B7: IKER FRANCISCO NORIEGA JIMENEZ
A8: 2 | B8: ELISA CAROLINA DIAZ LAGUNA | E8: 1
A9: 2 | B9: ALONSO CISNEROS SANCHEZ | E9: 1
A10: 3 | B10: MAXIMILIANO HERNÁNDEZ OROZCO | E10: 1
A11: 3 | B11: EMILIO MATEO OLIVARES CORTÉS | E11: 1
A12: 3 | B12: DIEGO PATRICIO FERNANDEZ VIERA | E12: 1
A13: 3 | B13: JESUS ANTONIO SEPULVEDA RODRIGUEZ | E13: 1
A14: 4 | B14: JOSUÉ SANTIAGO PÉREZ MEDINA
A15: 4 | B15: MIGUEL ALCARAZ AMEZCUA | E15: 1
A16: 4 | B16: ALEJANDRO CAMARENA LOPEZ | E16: 1
A17: 4 | B17: CAMILO RODRIGUEZ PACHECO | E17: 1
A18: 5 | B18: ESTEFANO ROLANDO BECERRA HERNANDEZ | E18: 1
A19: 5 | B19: JOSE EMILIANO VAZQUEZ NUÑO | E19: 1
A20: 5 | B20: ALBERTO ROBLES ARMENTA | E20: 1
A21: 5 | B21: LUCAS CONTRERAS PADRÓN
A22: 6 | B22: CHRISTIAN ULISES ACOSTA LOMELI
A23: 6 | B23: LEO LUCERO KOLB | E23: 1
A24: 6 | B24: ADRIANA ESPINOZA SALDAÑA | E24: 1
B25: MAURICIO LOZANO CASTILLERO
B26: IAN DE LA BARQUERA

Sheet Jornada 1
B3: Cancha 1 | C3: Puntos | D3: Jugadores | F3: Set 1 | J3: Set 2 | N3: Set 3 | Q3: anotados | S3: Ranking | T3: Puntos | U3: Jugadores
C4: 9 | D4: =Hoja2!B3 -> MAURICIO ALEJANDRO BAUTISTA | E4: =COUNTIF(C$4:C$7,">"&C4)+COUNTIF($C$4:C4,C4) -> 1 | F4: =D4 -> MAURICIO ALEJANDRO BAUTISTA | G4: VS | H4: =D6 -> IAN DE LA BARQUERA | J4: =D4 -> MAURICIO ALEJANDRO BAUTISTA | K4: VS | L4: =D5 -> MARIANO GOMEZ VUILLEUMIER | N4: =D4 -> MAURICIO ALEJANDRO BAUTISTA | O4: VS | P4: =D5 -> MARIANO GOMEZ VUILLEUMIER | Q4: =F6+J6+N6 -> 12 | S4: =COUNTIF(T$4:T$27,">"&T4)+1 -> 1 | T4: =$C$37 -> 11 | U4: =$D$37 -> JOSE EMILIANO VAZQUEZ NUÑO
C5: -1 | D5: =Hoja2!B4 -> MARIANO GOMEZ VUILLEUMIER | E5: =COUNTIF(C$4:C$7,">"&C5)+COUNTIF($C$4:C5,C5) -> 2 | F5: =D5 -> MARIANO GOMEZ VUILLEUMIER | H5: =D7 -> NICOLAS MAXIMILIANO BRILL HERRERA | J5: =D6 -> IAN DE LA BARQUERA | L5: =D7 -> NICOLAS MAXIMILIANO BRILL HERRERA | N5: =D7 -> NICOLAS MAXIMILIANO BRILL HERRERA | P5: =D6 -> IAN DE LA BARQUERA | Q5: =F6+L6+P6 -> 7 | S5: =COUNTIF(T$4:T$27,">"&T5)+1 -> 2 | T5: =$C$4 -> 9 | U5: =$D$4 -> MAURICIO ALEJANDRO BAUTISTA
C6: -7 | D6: IAN DE LA BARQUERA | E6: =COUNTIF(C$4:C$7,">"&C6)+COUNTIF($C$4:C6,C6) -> 4 | F6: 4 | H6: 0 | J6: 4 | L6: 3 | N6: 4 | P6: 0 | Q6: =H6+J6+P6 -> 4 | S6: =COUNTIF(T$4:T$27,">"&T6)+1 -> 3 | T6: =$C$45 -> 5 | U6: =$D$45 -> LEO LUCERO KOLB
C7: -1 | D7: =Hoja2!B5 -> NICOLAS MAXIMILIANO BRILL HERRERA | E7: =COUNTIF(C$4:C$7,">"&C7)+COUNTIF($C$4:C7,C7) -> 3 | Q7: =H6+L6+N6 -> 7 | S7: =COUNTIF(T$4:T$27,">"&T7)+1 -> 4 | T7: =$C$29 -> 4 | U7: =$D$29 -> MIGUEL ALCARAZ AMEZCUA
S8: =COUNTIF(T$4:T$27,">"&T8)+1 -> 4 | T8: =$C$12 -> 4 | U8: =$D$12 -> MARIANO NAVARRO LEAÑO
S9: =COUNTIF(T$4:T$27,">"&T9)+1 -> 6 | T9: =$C$47 -> 3 | U9: =$D$47 -> ADRIANA ESPINOZA SALDAÑA
S10: =COUNTIF(T$4:T$27,">"&T10)+1 -> 6 | T10: =$C$23 -> 3 | U10: =$D$23 -> JESUS ANTONIO SEPULVEDA RODRIGUEZ
B11: Cancha 2 | C11: Puntos | D11: Jugadores | F11: Set 1 | J11: Set 2 | N11: Set 3 | S11: =COUNTIF(T$4:T$27,">"&T11)+1 -> 8 | T11: =$C$31 -> 2 | U11: =$D$31 -> CAMILO RODRIGUEZ PACHECO
C12: 4 | D12: =Hoja2!B6 -> MARIANO NAVARRO LEAÑO | E12: =COUNTIF(C$12:C$15,">"&C12)+COUNTIF($C$12:C12,C12) -> 1 | F12: =D12 -> MARIANO NAVARRO LEAÑO | G12: VS | H12: =D14 -> ELISA CAROLINA DIAZ LAGUNA | J12: =D12 -> MARIANO NAVARRO LEAÑO | K12: VS | L12: =D13 -> IKER FRANCISCO NORIEGA JIMENEZ | N12: =D12 -> MARIANO NAVARRO LEAÑO | O12: VS | P12: =D13 -> IKER FRANCISCO NORIEGA JIMENEZ | Q12: =F14+J14+N14 -> 11 | S12: =COUNTIF(T$4:T$27,">"&T12)+1 -> 8 | T12: =$C$30 -> 2 | U12: =$D$30 -> ALEJANDRO CAMARENA LOPEZ
C13: -6 | D13: =Hoja2!B7 -> IKER FRANCISCO NORIEGA JIMENEZ | E13: =COUNTIF(C$12:C$15,">"&C13)+COUNTIF($C$12:C13,C13) -> 4 | F13: =D13 -> IKER FRANCISCO NORIEGA JIMENEZ | H13: =D15 -> ALONSO CISNEROS SANCHEZ | J13: =D14 -> ELISA CAROLINA DIAZ LAGUNA | L13: =D15 -> ALONSO CISNEROS SANCHEZ | N13: =D15 -> ALONSO CISNEROS SANCHEZ | P13: =D14 -> ELISA CAROLINA DIAZ LAGUNA | Q13: =F14+L14+P14 -> 6 | S13: =COUNTIF(T$4:T$27,">"&T13)+1 -> 8 | T13: =$C$14 -> 2 | U13: =$D$14 -> ELISA CAROLINA DIAZ LAGUNA
C14: 2 | D14: =Hoja2!B8 -> ELISA CAROLINA DIAZ LAGUNA | E14: =COUNTIF(C$12:C$15,">"&C14)+COUNTIF($C$12:C14,C14) -> 2 | F14: 3 | H14: 4 | J14: 4 | L14: 1 | N14: 4 | P14: 2 | Q14: =H14+J14+P14 -> 10 | S14: =COUNTIF(T$4:T$27,">"&T14)+1 -> 11 | T14: =$C$21 -> 1 | U14: =$D$21 -> EMILIO MATEO OLIVARES CORTÉS
C15: 0 | D15: =Hoja2!B9 -> ALONSO CISNEROS SANCHEZ | E15: =COUNTIF(C$12:C$15,">"&C15)+COUNTIF($C$12:C15,C15) -> 3 | Q15: =H14+L14+N14 -> 9 | S15: =COUNTIF(T$4:T$27,">"&T15)+1 -> 11 | T15: =$C$46 -> 1 | U15: =$D$46 -> MAURICIO LOZANO CASTILLERO
S16: =COUNTIF(T$4:T$27,">"&T16)+1 -> 11 | T16: =$C$22 -> 1 | U16: =$D$22 -> DIEGO PATRICIO FERNANDEZ VIERA
S17: =COUNTIF(T$4:T$27,">"&T17)+1 -> 14 | T17: =$C$15 -> 0 | U17: =$D$15 -> ALONSO CISNEROS SANCHEZ
S18: =COUNTIF(T$4:T$27,">"&T18)+1 -> 15 | T18: =$C$7 -> -1 | U18: =$D$7 -> NICOLAS MAXIMILIANO BRILL HERRERA
B19: Cancha 3 | C19: Puntos | D19: Jugadores | F19: Set 1 | J19: Set 2 | N19: Set 3 | S19: =COUNTIF(T$4:T$27,">"&T19)+1 -> 15 | T19: =$C$5 -> -1 | U19: =$D$5 -> MARIANO GOMEZ VUILLEUMIER
C20: -5 | D20: =Hoja2!B10 -> MAXIMILIANO HERNÁNDEZ OROZCO | E20: =COUNTIF(C$20:C$23,">"&C20)+COUNTIF($C$20:C20,C20) -> 4 | F20: =D20 -> MAXIMILIANO HERNÁNDEZ OROZCO | G20: VS | H20: =D22 -> DIEGO PATRICIO FERNANDEZ VIERA | J20: =D20 -> MAXIMILIANO HERNÁNDEZ OROZCO | K20: VS | L20: =D21 -> EMILIO MATEO OLIVARES CORTÉS | N20: =D20 -> MAXIMILIANO HERNÁNDEZ OROZCO | O20: VS | P20: =D21 -> EMILIO MATEO OLIVARES CORTÉS | S20: =COUNTIF(T$4:T$27,">"&T20)+1 -> 17 | T20: =$C$38 -> -3 | U20: =$D$38 -> ALBERTO ROBLES ARMENTA
C21: 1 | D21: =Hoja2!B11 -> EMILIO MATEO OLIVARES CORTÉS | E21: =COUNTIF(C$20:C$23,">"&C21)+COUNTIF($C$20:C21,C21) -> 2 | F21: =D21 -> EMILIO MATEO OLIVARES CORTÉS | H21: =D23 -> JESUS ANTONIO SEPULVEDA RODRIGUEZ | J21: =D22 -> DIEGO PATRICIO FERNANDEZ VIERA | L21: =D23 -> JESUS ANTONIO SEPULVEDA RODRIGUEZ | N21: =D23 -> JESUS ANTONIO SEPULVEDA RODRIGUEZ | P21: =D22 -> DIEGO PATRICIO FERNANDEZ VIERA | S21: =COUNTIF(T$4:T$27,">"&T21)+1 -> 17 | T21: =$C$36 -> -3 | U21: =$D$36 -> ESTEFANO ROLANDO BECERRA HERNANDEZ
C22: 1 | D22: =Hoja2!B12 -> DIEGO PATRICIO FERNANDEZ VIERA | E22: =COUNTIF(C$20:C$23,">"&C22)+COUNTIF($C$20:C22,C22) -> 3 | F22: 2 | H22: 4 | J22: 2 | L22: 4 | N22: 3 | P22: 4 | S22: =COUNTIF(T$4:T$27,">"&T22)+1 -> 19 | T22: =$C$20 -> -5 | U22: =$D$20 -> MAXIMILIANO HERNÁNDEZ OROZCO
C23: 3 | D23: =Hoja2!B13 -> JESUS ANTONIO SEPULVEDA RODRIGUEZ | E23: =COUNTIF(C$20:C$23,">"&C23)+COUNTIF($C$20:C23,C23) -> 1 | S23: =COUNTIF(T$4:T$27,">"&T23)+1 -> 19 | T23: =$C$39 -> -5 | U23: =$D$39 -> LUCAS CONTRERAS PADRÓN
S24: =COUNTIF(T$4:T$27,">"&T24)+1 -> 21 | T24: =$C$13 -> -6 | U24: =$D$13 -> IKER FRANCISCO NORIEGA JIMENEZ
S25: =COUNTIF(T$4:T$27,">"&T25)+1 -> 22 | T25: =$C$6 -> -7 | U25: =$D$6 -> IAN DE LA BARQUERA
S26: =COUNTIF(T$4:T$27,">"&T26)+1 -> 23 | T26: =$C$28 -> -8 | U26: =$D$28 -> JOSUÉ SANTIAGO PÉREZ MEDINA
B27: Cancha 4 | C27: Puntos | D27: Jugadores | F27: Set 1 | J27: Set 2 | N27: Set 3 | S27: =COUNTIF(T$4:T$27,">"&T27)+1 -> 24 | T27: =$C$44 -> -9 | U27: =$D$44 -> CHRISTIAN ULISES ACOSTA LOMELI
C28: -8 | D28: =Hoja2!B14 -> JOSUÉ SANTIAGO PÉREZ MEDINA | E28: =COUNTIF(C$28:C$31,">"&C28)+COUNTIF($C$28:C28,C28) -> 4 | F28: =D28 -> JOSUÉ SANTIAGO PÉREZ MEDINA | G28: VS | H28: =D30 -> ALEJANDRO CAMARENA LOPEZ | J28: =D28 -> JOSUÉ SANTIAGO PÉREZ MEDINA | K28: VS | L28: =D29 -> MIGUEL ALCARAZ AMEZCUA | N28: =D28 -> JOSUÉ SANTIAGO PÉREZ MEDINA | O28: VS | P28: =D29 -> MIGUEL ALCARAZ AMEZCUA
C29: 4 | D29: =Hoja2!B15 -> MIGUEL ALCARAZ AMEZCUA | E29: =COUNTIF(C$28:C$31,">"&C29)+COUNTIF($C$28:C29,C29) -> 1 | F29: =D29 -> MIGUEL ALCARAZ AMEZCUA | H29: =D31 -> CAMILO RODRIGUEZ PACHECO | J29: =D30 -> ALEJANDRO CAMARENA LOPEZ | L29: =D31 -> CAMILO RODRIGUEZ PACHECO | N29: =D31 -> CAMILO RODRIGUEZ PACHECO | P29: =D30 -> ALEJANDRO CAMARENA LOPEZ
C30: 2 | D30: =Hoja2!B16 -> ALEJANDRO CAMARENA LOPEZ | E30: =COUNTIF(C$28:C$31,">"&C30)+COUNTIF($C$28:C30,C30) -> 2 | F30: 2 | H30: 4 | J30: 1 | L30: 4 | N30: 1 | P30: 4
C31: 2 | D31: =Hoja2!B17 -> CAMILO RODRIGUEZ PACHECO | E31: =COUNTIF(C$28:C$31,">"&C31)+COUNTIF($C$28:C31,C31) -> 3
B35: Cancha 5 | C35: Puntos | D35: Jugadores | F35: Set 1 | J35: Set 2 | N35: Set 3
C36: -3 | D36: =Hoja2!B18 -> ESTEFANO ROLANDO BECERRA HERNANDEZ | E36: =COUNTIF(C$36:C$39,">"&C36)+COUNTIF($C$36:C36,C36) -> 2 | F36: =D36 -> ESTEFANO ROLANDO BECERRA HERNANDEZ | G36: VS | H36: =D38 -> ALBERTO ROBLES ARMENTA | J36: =D36 -> ESTEFANO ROLANDO BECERRA HERNANDEZ | K36: VS | L36: =D37 -> JOSE EMILIANO VAZQUEZ NUÑO | N36: =D36 -> ESTEFANO ROLANDO BECERRA HERNANDEZ | O36: VS | P36: =D37 -> JOSE EMILIANO VAZQUEZ NUÑO
C37: 11 | D37: =Hoja2!B19 -> JOSE EMILIANO VAZQUEZ NUÑO | E37: =COUNTIF(C$36:C$39,">"&C37)+COUNTIF($C$36:C37,C37) -> 1 | F37: =D37 -> JOSE EMILIANO VAZQUEZ NUÑO | H37: =D39 -> LUCAS CONTRERAS PADRÓN | J37: =D38 -> ALBERTO ROBLES ARMENTA | L37: =D39 -> LUCAS CONTRERAS PADRÓN | N37: =D39 -> LUCAS CONTRERAS PADRÓN | P37: =D38 -> ALBERTO ROBLES ARMENTA
C38: -3 | D38: =Hoja2!B20 -> ALBERTO ROBLES ARMENTA | E38: =COUNTIF(C$36:C$39,">"&C38)+COUNTIF($C$36:C38,C38) -> 3 | F38: 4 | H38: 0 | J38: 1 | L38: 4 | N38: 0 | P38: 4
C39: -5 | D39: =Hoja2!B21 -> LUCAS CONTRERAS PADRÓN | E39: =COUNTIF(C$36:C$39,">"&C39)+COUNTIF($C$36:C39,C39) -> 4
B43: Cancha 6 | C43: Puntos | D43: Jugadores | F43: Set 1 | J43: Set 2 | N43: Set 3
C44: -9 | D44: =Hoja2!B22 -> CHRISTIAN ULISES ACOSTA LOMELI | E44: =COUNTIF(C$44:C$47,">"&C44)+COUNTIF($C$44:C44,C44) -> 4 | F44: =D44 -> CHRISTIAN ULISES ACOSTA LOMELI | G44: VS | H44: =D46 -> MAURICIO LOZANO CASTILLERO | J44: =D44 -> CHRISTIAN ULISES ACOSTA LOMELI | K44: VS | L44: =D45 -> LEO LUCERO KOLB | N44: =D44 -> CHRISTIAN ULISES ACOSTA LOMELI | O44: VS | P44: =D45 -> LEO LUCERO KOLB
C45: 5 | D45: =Hoja2!B23 -> LEO LUCERO KOLB | E45: =COUNTIF(C$44:C$47,">"&C45)+COUNTIF($C$44:C45,C45) -> 1 | F45: =D45 -> LEO LUCERO KOLB | H45: =D47 -> ADRIANA ESPINOZA SALDAÑA | J45: =D46 -> MAURICIO LOZANO CASTILLERO | L45: =D47 -> ADRIANA ESPINOZA SALDAÑA | N45: =D47 -> ADRIANA ESPINOZA SALDAÑA | P45: =D46 -> MAURICIO LOZANO CASTILLERO
C46: 1 | D46: =Hoja2!B25 -> MAURICIO LOZANO CASTILLERO | E46: =COUNTIF(C$44:C$47,">"&C46)+COUNTIF($C$44:C46,C46) -> 3 | F46: 2 | H46: 4 | J46: 0 | L46: 4 | N46: 1 | P46: 4
C47: 3 | D47: =Hoja2!B24 -> ADRIANA ESPINOZA SALDAÑA | E47: =COUNTIF(C$44:C$47,">"&C47)+COUNTIF($C$44:C47,C47) -> 2
B51: Cancha 7 | C51: Puntos | D51: Jugadores | F51: Set 1 | J51: Set 2 | N51: Set 3
...

Sheet Jornada 2 (1)
S2: Ranking de la jornada
B3: Cancha 1 18:00 HS | C3: Puntos | D3: Jugadores | F3: Set 1 | J3: Set 2 | N3: Set 3 | S3: Ranking | T3: Puntos | U3: Jugadores
C4: =(F6-H6)+(J6-L6)+(N6-P6) -> 11 | D4: {=INDEX('Jornada 1'!D$4:D$7, MATCH(1,'Jornada 1'!E$4:E$7,0))} -> MAURICIO ALEJANDRO BAUTISTA | E4: =COUNTIF(C$4:C$7,">"&C4)+COUNTIF($C$4:C4,C4) -> 1 | F4: =D4 -> MAURICIO ALEJANDRO BAUTISTA | G4: VS | H4: =D6 -> NICOLAS MAXIMILIANO BRILL HERRERA | J4: =D4 -> MAURICIO ALEJANDRO BAUTISTA | K4: VS | L4: =D5 -> MARIANO GOMEZ VUILLEUMIER | N4: =D4 -> MAURICIO ALEJANDRO BAUTISTA | O4: VS | P4: =D5 -> MARIANO GOMEZ VUILLEUMIER | S4: =COUNTIF(T$4:T$27,">"&T4)+1 -> 1 | T4: =$C$4 -> 11 | U4: =$D$4 -> MAURICIO ALEJANDRO BAUTISTA
C5: =(F6-H6)+(L6-J6)+(P6-N6) -> -3 | D5: {=INDEX('Jornada 1'!D$4:D$7, MATCH(2,'Jornada 1'!E$4:E$7,0))} -> MARIANO GOMEZ VUILLEUMIER | E5: =COUNTIF(C$4:C$7,">"&C5)+COUNTIF($C$4:C5,C5) -> 2 | F5: =D5 -> MARIANO GOMEZ VUILLEUMIER | H5: =D7 -> MARIANO NAVARRO LEAÑO | J5: =D6 -> NICOLAS MAXIMILIANO BRILL HERRERA | L5: =D7 -> MARIANO NAVARRO LEAÑO | N5: =D7 -> MARIANO NAVARRO LEAÑO | P5: =D6 -> NICOLAS MAXIMILIANO BRILL HERRERA | S5: =COUNTIF(T$4:T$27,">"&T5)+1 -> 2 | T5: =$C$11 -> 9 | U5: =$D$11 -> IAN DE LA BARQUERA
C6: =(H6-F6)+(J6-L6)+(P6-N6) -> -3 | D6: {=IF('Jornada 1'!G76=1,INDEX('Jornada 1'!D$4:D$7,MATCH(3,'Jornada 1'!E$4:E$7,0)),INDEX('Jornada 1'!D$12:D$15,MATCH(1,'Jornada 1'!E$12:E$15,0)))} -> NICOLAS MAXIMILIANO BRILL HERRERA | E6: =COUNTIF(C$4:C$7,">"&C6)+COUNTIF($C$4:C6,C6) -> 3 | F6: 4 | H6: 0 | J6: 4 | L6: 0 | N6: 4 | P6: 1 | S6: =COUNTIF(T$4:T$27,">"&T6)+1 -> 2 | T6: =$C$28 -> 9 | U6: =$D$28 -> MAURICIO LOZANO CASTILLERO
C7: =(H6-F6)+(L6-J6)+(N6-P6) -> -5 | D7: {=IF('Jornada 1'!G76=1,INDEX('Jornada 1'!D$12:D$15,MATCH(1,'Jornada 1'!E$12:E$15,0)),INDEX('Jornada 1'!D$12:D$15,MATCH(2,'Jornada 1'!E$12:E$15,0)))} -> MARIANO NAVARRO LEAÑO | E7: =COUNTIF(C$4:C$7,">"&C7)+COUNTIF($C$4:C7,C7) -> 4 | S7: =COUNTIF(T$4:T$27,">"&T7)+1 -> 4 | T7: =$C$18 -> 8 | U7: =$D$18 -> IKER FRANCISCO NORIEGA JIMENEZ
S8: =COUNTIF(T$4:T$27,">"&T8)+1 -> 5 | T8: =$C$40 -> 5 | U8: =$D$40 -> LEO LUCERO KOLB
S9: =COUNTIF(T$4:T$27,">"&T9)+1 -> 6 | T9: =$C$32 -> 4 | U9: =$D$32 -> MAXIMILIANO HERNÁNDEZ OROZCO
B10: Cancha 2 18:00 HS | C10: Puntos | D10: Jugadores | F10: Set 1 | J10: Set 2 | N10: Set 3 | S10: =COUNTIF(T$4:T$27,">"&T10)+1 -> 6 | T10: =$C$34 -> 4 | U10: =$D$34 -> ESTEFANO ROLANDO BECERRA HERNANDEZ
C11: =(F13-H13)+(J13-L13)+(N13-P13) -> 9 | D11: {=IF('Jornada 1'!G$76=1,INDEX('Jornada 1'!D$4:D$7,MATCH(4,'Jornada 1'!E$4:E$7,0)),INDEX('Jornada 1'!D$4:D$7,MATCH(3,'Jornada 1'!E$4:E$7,0)))} -> IAN DE LA BARQUERA | E11: =COUNTIF(C$11:C$14,">"&C11)+COUNTIF($C$11:C11,C11) -> 1 | F11: =D11 -> IAN DE LA BARQUERA | G11: VS | H11: =D13 -> ALONSO CISNEROS SANCHEZ | J11: =D11 -> IAN DE LA BARQUERA | K11: VS | L11: =D12 -> ELISA CAROLINA DIAZ LAGUNA | N11: =D11 -> IAN DE LA BARQUERA | O11: VS | P11: =D12 -> ELISA CAROLINA DIAZ LAGUNA | S11: =COUNTIF(T$4:T$27,">"&T11)+1 -> 8 | T11: =$C$39 -> 3 | U11: =$D$39 -> LUCAS CONTRERAS PADRÓN
C12: =(F13-H13)+(L13-J13)+(P13-N13) -> -1 | D12: {=IF('Jornada 1'!G$76=1,INDEX('Jornada 1'!D$12:D$15,MATCH(2,'Jornada 1'!E$12:E$15,0)),INDEX('Jornada 1'!D$4:D$7,MATCH(4,'Jornada 1'!E$4:E$7,0)))} -> ELISA CAROLINA DIAZ LAGUNA | E12: =COUNTIF(C$11:C$14,">"&C12)+COUNTIF($C$11:C12,C12) -> 2 | F12: =D12 -> ELISA CAROLINA DIAZ LAGUNA | H12: =D14 -> JESUS ANTONIO SEPULVEDA RODRIGUEZ | J12: =D13 -> ALONSO CISNEROS SANCHEZ | L12: =D14 -> JESUS ANTONIO SEPULVEDA RODRIGUEZ | N12: =D14 -> JESUS ANTONIO SEPULVEDA RODRIGUEZ | P12: =D13 -> ALONSO CISNEROS SANCHEZ | S12: =COUNTIF(T$4:T$27,">"&T12)+1 -> 8 | T12: =$C$41 -> 3 | U12: =$D$41 -> ADRIANA ESPINOZA SALDAÑA
C13: =(H13-F13)+(J13-L13)+(P13-N13) -> -5 | D13: {=IF('Jornada 1'!G$76=1,INDEX('Jornada 1'!D$12:D$15,MATCH(3,'Jornada 1'!E$12:E$15,0)),INDEX('Jornada 1'!D$20:D$23,MATCH(1,'Jornada 1'!E$20:E$23,0)))} -> ALONSO CISNEROS SANCHEZ | E13: =COUNTIF(C$11:C$14,">"&C13)+COUNTIF($C$11:C13,C13) -> 4 | F13: 4 | H13: 0 | J13: 4 | L13: 2 | N13: 4 | P13: 1 | S13: =COUNTIF(T$4:T$27,">"&T13)+1 -> 10 | T13: =$C$33 -> 2 | U13: =$D$33 -> JOSUÉ SANTIAGO PÉREZ MEDINA
C14: =(H13-F13)+(L13-J13)+(N13-P13) -> -3 | D14: {=IF('Jornada 1'!G$76=1,INDEX('Jornada 1'!D$20:D$23,MATCH(1,'Jornada 1'!E$20:E$23,0)),INDEX('Jornada 1'!D$20:D$23,MATCH(2,'Jornada 1'!E$20:E$23,0)))} -> JESUS ANTONIO SEPULVEDA RODRIGUEZ | E14: =COUNTIF(C$11:C$14,">"&C14)+COUNTIF($C$11:C14,C14) -> 3 | S14: =COUNTIF(T$4:T$27,">"&T14)+1 -> 11 | T14: =$C$20 -> 0 | U14: =$D$20 -> DIEGO PATRICIO FERNANDEZ VIERA
S15: =COUNTIF(T$4:T$27,">"&T15)+1 -> 12 | T15: =$C$12 -> -1 | U15: =$D$12 -> ELISA CAROLINA DIAZ LAGUNA
S16: =COUNTIF(T$4:T$27,">"&T16)+1 -> 12 | T16: =$C$27 -> -1 | U16: =$D$27 -> JOSE EMILIANO VAZQUEZ NUÑO
B17: Cancha 3 18:00 HS | C17: Puntos | D17: Jugadores | F17: Set 1 | J17: Set 2 | N17: Set 3 | S17: =COUNTIF(T$4:T$27,">"&T17)+1 -> 14 | T17: =$C$5 -> -3 | U17: =$D$5 -> MARIANO GOMEZ VUILLEUMIER
C18: =(F20-H20)+(J20-L20)+(N20-P20) -> 8 | D18: {=IF('Jornada 1'!G$76=1,INDEX('Jornada 1'!D$12:D$15,MATCH(4,'Jornada 1'!E$12:E$15,0)),INDEX('Jornada 1'!D$12:D$15,MATCH(3,'Jornada 1'!E$12:E$15,0)))} -> IKER FRANCISCO NORIEGA JIMENEZ | E18: =COUNTIF(C$18:C$21,">"&C18)+COUNTIF($C$18:C18,C18) -> 1 | F18: =D18 -> IKER FRANCISCO NORIEGA JIMENEZ | G18: VS | H18: =D20 -> DIEGO PATRICIO FERNANDEZ VIERA | J18: =D18 -> IKER FRANCISCO NORIEGA JIMENEZ | K18: VS | L18: =D19 -> EMILIO MATEO OLIVARES CORTÉS | N18: =D18 -> IKER FRANCISCO NORIEGA JIMENEZ | O18: VS | P18: =D19 -> EMILIO MATEO OLIVARES CORTÉS | S18: =COUNTIF(T$4:T$27,">"&T18)+1 -> 14 | T18: =$C$6 -> -3 | U18: =$D$6 -> NICOLAS MAXIMILIANO BRILL HERRERA
C19: =(F20-H20)+(L20-J20)+(P20-N20) -> -4 | D19: {=IF('Jornada 1'!G$76=1,INDEX('Jornada 1'!D$20:D$23,MATCH(2,'Jornada 1'!E$20:E$23,0)),INDEX('Jornada 1'!D$12:D$15,MATCH(4,'Jornada 1'!E$12:E$15,0)))} -> EMILIO MATEO OLIVARES CORTÉS | E19: =COUNTIF(C$18:C$21,">"&C19)+COUNTIF($C$18:C19,C19) -> 3 | F19: =D19 -> EMILIO MATEO OLIVARES CORTÉS | H19: =D21 -> MIGUEL ALCARAZ AMEZCUA | J19: =D20 -> DIEGO PATRICIO FERNANDEZ VIERA | L19: =D21 -> MIGUEL ALCARAZ AMEZCUA | N19: =D21 -> MIGUEL ALCARAZ AMEZCUA | P19: =D20 -> DIEGO PATRICIO FERNANDEZ VIERA | S19: =COUNTIF(T$4:T$27,">"&T19)+1 -> 14 | T19: =$C$14 -> -3 | U19: =$D$14 -> JESUS ANTONIO SEPULVEDA RODRIGUEZ
C20: =(H20-F20)+(J20-L20)+(P20-N20) -> 0 | D20: {=IF('Jornada 1'!G$76=1,INDEX('Jornada 1'!D$20:D$23,MATCH(3,'Jornada 1'!E$20:E$23,0)),INDEX('Jornada 1'!D$28:D$31,MATCH(1,'Jornada 1'!E$28:E$31,0)))} -> DIEGO PATRICIO FERNANDEZ VIERA | E20: =COUNTIF(C$18:C$21,">"&C20)+COUNTIF($C$18:C20,C20) -> 2 | F20: 4 | H20: 2 | J20: 4 | L20: 0 | N20: 4 | P20: 2 | S20: =COUNTIF(T$4:T$27,">"&T20)+1 -> 14 | T20: =$C$26 -> -3 | U20: =$D$26 -> CAMILO RODRIGUEZ PACHECO
C21: =(H20-F20)+(L20-J20)+(N20-P20) -> -4 | D21: {=IF('Jornada 1'!G$76=1,INDEX('Jornada 1'!D$28:D$31,MATCH(1,'Jornada 1'!E$28:E$31,0)),INDEX('Jornada 1'!D$28:D$31,MATCH(2,'Jornada 1'!E$28:E$31,0)))} -> MIGUEL ALCARAZ AMEZCUA | E21: =COUNTIF(C$18:C$21,">"&C21)+COUNTIF($C$18:C21,C21) -> 4 | S21: =COUNTIF(T$4:T$27,">"&T21)+1 -> 18 | T21: =$C$19 -> -4 | U21: =$D$19 -> EMILIO MATEO OLIVARES CORTÉS
S22: =COUNTIF(T$4:T$27,">"&T22)+1 -> 18 | T22: =$C$21 -> -4 | U22: =$D$21 -> MIGUEL ALCARAZ AMEZCUA
S23: =COUNTIF(T$4:T$27,">"&T23)+1 -> 20 | T23: =$C$7 -> -5 | U23: =$D$7 -> MARIANO NAVARRO LEAÑO
B24: Cancha 4 17:00 HS | C24: Puntos | D24: Jugadores | F24: Set 1 | J24: Set 2 | N24: Set 3 | S24: =COUNTIF(T$4:T$27,">"&T24)+1 -> 20 | T24: =$C$13 -> -5 | U24: =$D$13 -> ALONSO CISNEROS SANCHEZ
C25: =(F27-H27)+(J27-L27)+(N27-P27) -> -5 | D25: {=IF('Jornada 1'!G$76=1,INDEX('Jornada 1'!D$28:D$31,MATCH(2,'Jornada 1'!E$28:E$31,0)),INDEX('Jornada 1'!D$20:D$23,MATCH(4,'Jornada 1'!E$20:E$23,0)))} -> ALEJANDRO CAMARENA LOPEZ | E25: =COUNTIF(C$25:C$28,">"&C25)+COUNTIF($C$25:C25,C25) -> 4 | F25: =D25 -> ALEJANDRO CAMARENA LOPEZ | G25: VS | H25: =D27 -> JOSE EMILIANO VAZQUEZ NUÑO | J25: =D25 -> ALEJANDRO CAMARENA LOPEZ | K25: VS | L25: =D26 -> CAMILO RODRIGUEZ PACHECO | N25: =D25 -> ALEJANDRO CAMARENA LOPEZ | O25: VS | P25: =D26 -> CAMILO RODRIGUEZ PACHECO | S25: =COUNTIF(T$4:T$27,">"&T25)+1 -> 20 | T25: =$C$25 -> -5 | U25: =$D$25 -> ALEJANDRO CAMARENA LOPEZ
C26: =(F27-H27)+(L27-J27)+(P27-N27) -> -3 | D26: {=IF('Jornada 1'!G$76=1,INDEX('Jornada 1'!D$28:D$31,MATCH(3,'Jornada 1'!E$28:E$31,0)),INDEX('Jornada 1'!D$36:D$39,MATCH(1,'Jornada 1'!E$36:E$39,0)))} -> CAMILO RODRIGUEZ PACHECO | E26: =COUNTIF(C$25:C$28,">"&C26)+COUNTIF($C$25:C26,C26) -> 3 | F26: =D26 -> CAMILO RODRIGUEZ PACHECO | H26: =D28 -> MAURICIO LOZANO CASTILLERO | J26: =D27 -> JOSE EMILIANO VAZQUEZ NUÑO | L26: =D28 -> MAURICIO LOZANO CASTILLERO | N26: =D28 -> MAURICIO LOZANO CASTILLERO | P26: =D27 -> JOSE EMILIANO VAZQUEZ NUÑO | S26: =COUNTIF(T$4:T$27,">"&T26)+1 -> 23 | T26: =$C$35 -> -10 | U26: =$D$35 -> ALBERTO ROBLES ARMENTA
C27: =(H27-F27)+(J27-L27)+(P27-N27) -> -1 | D27: {=IF('Jornada 1'!G$76=1,INDEX('Jornada 1'!D$36:D$39,MATCH(1,'Jornada 1'!E$36:E$39,0)),INDEX('Jornada 1'!D$36:D$39,MATCH(2,'Jornada 1'!E$36:E$39,0)))} -> JOSE EMILIANO VAZQUEZ NUÑO | E27: =COUNTIF(C$25:C$28,">"&C27)+COUNTIF($C$25:C27,C27) -> 2 | F27: 0 | H27: 4 | J27: 1 | L27: 4 | N27: 4 | P27: 2 | S27: =COUNTIF(T$4:T$27,">"&T27)+1 -> 24 | T27: =$C$42 -> -11 | U27: =$D$42 -> CHRISTIAN ULISES ACOSTA LOMELI
C28: =(H27-F27)+(L27-J27)+(N27-P27) -> 9 | D28: MAURICIO LOZANO CASTILLERO | E28: =COUNTIF(C$25:C$28,">"&C28)+COUNTIF($C$25:C28,C28) -> 1
B31: Cancha 5 17:00 HS | C31: Puntos | D31: Jugadores | F31: Set 1 | J31: Set 2 | N31: Set 3
C32: =(F34-H34)+(J34-L34)+(N34-P34) -> 4 | D32: {=IF('Jornada 1'!G$76=1,INDEX('Jornada 1'!D$20:D$23,MATCH(4,'Jornada 1'!E$20:E$23,0)),INDEX('Jornada 1'!D$20:D$23,MATCH(3,'Jornada 1'!E$20:E$23,0)))} -> MAXIMILIANO HERNÁNDEZ OROZCO | E32: =COUNTIF(C$32:C$35,">"&C32)+COUNTIF($C$32:C32,C32) -> 1 | F32: =D32 -> MAXIMILIANO HERNÁNDEZ OROZCO | G32: VS | H32: =D34 -> ESTEFANO ROLANDO BECERRA HERNANDEZ | J32: =D32 -> MAXIMILIANO HERNÁNDEZ OROZCO | K32: VS | L32: =D33 -> JOSUÉ SANTIAGO PÉREZ MEDINA | N32: =D32 -> MAXIMILIANO HERNÁNDEZ OROZCO | O32: VS | P32: =D33 -> JOSUÉ SANTIAGO PÉREZ MEDINA
C33: =(F34-H34)+(L34-J34)+(P34-N34) -> 2 | D33: {=IF('Jornada 1'!G$76=1,INDEX('Jornada 1'!D$28:D$31,MATCH(4,'Jornada 1'!E$28:E$31,0)),INDEX('Jornada 1'!D$28:D$31,MATCH(3,'Jornada 1'!E$28:E$31,0)))} -> JOSUÉ SANTIAGO PÉREZ MEDINA | E33: =COUNTIF(C$32:C$35,">"&C33)+COUNTIF($C$32:C33,C33) -> 3 | F33: =D33 -> JOSUÉ SANTIAGO PÉREZ MEDINA | H33: =D35 -> ALBERTO ROBLES ARMENTA | J33: =D34 -> ESTEFANO ROLANDO BECERRA HERNANDEZ | L33: =D35 -> ALBERTO ROBLES ARMENTA | N33: =D35 -> ALBERTO ROBLES ARMENTA | P33: =D34 -> ESTEFANO ROLANDO BECERRA HERNANDEZ
C34: =(H34-F34)+(J34-L34)+(P34-N34) -> 4 | D34: {=IF('Jornada 1'!G$76=1,INDEX('Jornada 1'!D$36:D$39,MATCH(2,'Jornada 1'!E$36:E$39,0)),INDEX('Jornada 1'!D$28:D$31,MATCH(4,'Jornada 1'!E$28:E$31,0)))} -> ESTEFANO ROLANDO BECERRA HERNANDEZ | E34: =COUNTIF(C$32:C$35,">"&C34)+COUNTIF($C$32:C34,C34) -> 2 | F34: 4 | H34: 1 | J34: 4 | L34: 0 | N34: 1 | P34: 4
C35: =(H34-F34)+(L34-J34)+(N34-P34) -> -10 | D35: {=IF('Jornada 1'!G$76=1,INDEX('Jornada 1'!D$36:D$39,MATCH(3,'Jornada 1'!E$36:E$39,0)),INDEX('Jornada 1'!D$44:D$47,MATCH(1,'Jornada 1'!E$44:E$47,0)))} -> ALBERTO ROBLES ARMENTA | E35: =COUNTIF(C$32:C$35,">"&C35)+COUNTIF($C$32:C35,C35) -> 4
B38: Cancha 6 17:00 HS | C38: Puntos | D38: Jugadores | F38: Set 1 | J38: Set 2 | N38: Set 3
C39: =(F41-H41)+(J41-L41)+(N41-P41) -> 3 | D39: {=IF('Jornada 1'!G$76=1,INDEX('Jornada 1'!D$36:D$39,MATCH(4,'Jornada 1'!E$36:E$39,0)),INDEX('Jornada 1'!D$36:D$39,MATCH(3,'Jornada 1'!E$36:E$39,0)))} -> LUCAS CONTRERAS PADRÓN | E39: =COUNTIF(C$39:C$42,">"&C39)+COUNTIF($C$39:C39,C39) -> 2 | F39: =D39 -> LUCAS CONTRERAS PADRÓN | G39: VS | H39: =D41 -> ADRIANA ESPINOZA SALDAÑA | J39: =D39 -> LUCAS CONTRERAS PADRÓN | K39: VS | L39: =D40 -> LEO LUCERO KOLB | N39: =D39 -> LUCAS CONTRERAS PADRÓN | O39: VS | P39: =D40 -> LEO LUCERO KOLB
C40: =(F41-H41)+(L41-J41)+(P41-N41) -> 5 | D40: {=IF('Jornada 1'!G$76=1,INDEX('Jornada 1'!D$44:D$47,MATCH(1,'Jornada 1'!E$44:E$47,0)),INDEX('Jornada 1'!D$44:D$47,MATCH(2,'Jornada 1'!E$44:E$47,0)))} -> LEO LUCERO KOLB | E40: =COUNTIF(C$39:C$42,">"&C40)+COUNTIF($C$39:C40,C40) -> 1 | F40: =D40 -> LEO LUCERO KOLB | H40: =D42 -> CHRISTIAN ULISES ACOSTA LOMELI | J40: =D41 -> ADRIANA ESPINOZA SALDAÑA | L40: =D42 -> CHRISTIAN ULISES ACOSTA LOMELI | N40: =D42 -> CHRISTIAN ULISES ACOSTA LOMELI | P40: =D41 -> ADRIANA ESPINOZA SALDAÑA
C41: =(H41-F41)+(J41-L41)+(P41-N41) -> 3 | D41: {=IF('Jornada 1'!G$76=1,INDEX('Jornada 1'!D$44:D$47,MATCH(2,'Jornada 1'!E$44:E$47,0)),INDEX('Jornada 1'!D$36:D$39,MATCH(4,'Jornada 1'!E$36:E$39,0)))} -> ADRIANA ESPINOZA SALDAÑA | E41: =COUNTIF(C$39:C$42,">"&C41)+COUNTIF($C$39:C41,C41) -> 3 | F41: 4 | H41: 0 | J41: 4 | L41: 1 | N41: 0 | P41: 4
C42: =(H41-F41)+(L41-J41)+(N41-P41) -> -11 | D42: {=INDEX('Jornada 1'!D$40:D$47,MATCH(4,'Jornada 1'!E$40:E$47,0))} -> CHRISTIAN ULISES ACOSTA LOMELI | E42: =COUNTIF(C$39:C$42,">"&C42)+COUNTIF($C$39:C42,C42) -> 4
B45: Cancha 7 | C45: Puntos | D45: Jugadores | F45: Set 1 | J45: Set 2 | N45: Set 3
C46: =(F48-H48)+(J48-L48)+(N48-P48) -> 0 | D46: Jugador 1 | F46: =D46 -> Jugador 1 | G46: VS | H46: =D48 -> Jugador 3 | J46: =D46 -> Jugador 1 | K46: VS | L46: =D47 -> Jugador 2 | N46: =D46 -> Jugador 1 | O46: VS | P46: =D47 -> Jugador 2
C47: =(F48-H48)+(L48-J48)+(P48-N48) -> 0 | D47: Jugador 2 | F47: =D47 -> Jugador 2 | H47: =D49 -> Jugador 4 | J47: =D48 -> Jugador 3 | L47: =D49 -> Jugador 4 | N47: =D49 -> Jugador 4 | P47: =D48 -> Jugador 3
...

Sheet Jornada 2 partidos
F1: CANCHA 1
S2: Ranking de la jornada
B3: Cancha 1 18:00 HS | C3: Puntos | D3: Jugadores | F3: Set 1 | J3: Set 2 | N3: Set 3 | S3: Ranking | T3: Puntos | U3: Jugadores
C4: =(F6-H6)+(J6-L6)+(N6-P6) -> 11 | D4: {=INDEX('Jornada 1'!D$4:D$7, MATCH(1,'Jornada 1'!E$4:E$7,0))} -> MAURICIO ALEJANDRO BAUTISTA | E4: =COUNTIF(C$4:C$7,">"&C4)+COUNTIF($C$4:C4,C4) -> 1 | F4: =D4 -> MAURICIO ALEJANDRO BAUTISTA | G4: VS | H4: =D6 -> NICOLAS MAXIMILIANO BRILL HERRERA | J4: =D4 -> MAURICIO ALEJANDRO BAUTISTA | K4: VS | L4: =D5 -> MARIANO GOMEZ VUILLEUMIER | N4: =D4 -> MAURICIO ALEJANDRO BAUTISTA | O4: VS | P4: =D5 -> MARIANO GOMEZ VUILLEUMIER | S4: =COUNTIF(T$4:T$27,">"&T4)+1 -> 1 | T4: =$C$4 -> 11 | U4: =$D$4 -> MAURICIO ALEJANDRO BAUTISTA
C5: =(F6-H6)+(L6-J6)+(P6-N6) -> -3 | D5: {=INDEX('Jornada 1'!D$4:D$7, MATCH(2,'Jornada 1'!E$4:E$7,0))} -> MARIANO GOMEZ VUILLEUMIER | E5: =COUNTIF(C$4:C$7,">"&C5)+COUNTIF($C$4:C5,C5) -> 2 | F5: =D5 -> MARIANO GOMEZ VUILLEUMIER | H5: =D7 -> MARIANO NAVARRO LEAÑO | J5: =D6 -> NICOLAS MAXIMILIANO BRILL HERRERA | L5: =D7 -> MARIANO NAVARRO LEAÑO | N5: =D7 -> MARIANO NAVARRO LEAÑO | P5: =D6 -> NICOLAS MAXIMILIANO BRILL HERRERA | S5: =COUNTIF(T$4:T$27,">"&T5)+1 -> 2 | T5: =$C$11 -> 9 | U5: =$D$11 -> IAN DE LA BARQUERA
C6: =(H6-F6)+(J6-L6)+(P6-N6) -> -3 | D6: {=IF('Jornada 1'!G76=1,INDEX('Jornada 1'!D$4:D$7,MATCH(3,'Jornada 1'!E$4:E$7,0)),INDEX('Jornada 1'!D$12:D$15,MATCH(1,'Jornada 1'!E$12:E$15,0)))} -> NICOLAS MAXIMILIANO BRILL HERRERA | E6: =COUNTIF(C$4:C$7,">"&C6)+COUNTIF($C$4:C6,C6) -> 3 | F6: 4 | H6: 0 | J6: 4 | L6: 0 | N6: 4 | P6: 1 | S6: =COUNTIF(T$4:T$27,">"&T6)+1 -> 2 | T6: =$C$28 -> 9 | U6: =$D$28 -> MAURICIO LOZANO CASTILLERO
C7: =(H6-F6)+(L6-J6)+(N6-P6) -> -5 | D7: {=IF('Jornada 1'!G76=1,INDEX('Jornada 1'!D$12:D$15,MATCH(1,'Jornada 1'!E$12:E$15,0)),INDEX('Jornada 1'!D$12:D$15,MATCH(2,'Jornada 1'!E$12:E$15,0)))} -> MARIANO NAVARRO LEAÑO | E7: =COUNTIF(C$4:C$7,">"&C7)+COUNTIF($C$4:C7,C7) -> 4 | S7: =COUNTIF(T$4:T$27,">"&T7)+1 -> 4 | T7: =$C$18 -> 8 | U7: =$D$18 -> IKER FRANCISCO NORIEGA JIMENEZ
S8: =COUNTIF(T$4:T$27,">"&T8)+1 -> 5 | T8: =$C$40 -> 5 | U8: =$D$40 -> LEO LUCERO KOLB
S9: =COUNTIF(T$4:T$27,">"&T9)+1 -> 6 | T9: =$C$32 -> 4 | U9: =$D$32 -> MAXIMILIANO HERNÁNDEZ OROZCO
B10: Cancha 2 18:00 HS | C10: Puntos | D10: Jugadores | F10: Set 1 | J10: Set 2 | N10: Set 3 | S10: =COUNTIF(T$4:T$27,">"&T10)+1 -> 6 | T10: =$C$34 -> 4 | U10: =$D$34 -> ESTEFANO ROLANDO BECERRA HERNANDEZ
C11: =(F13-H13)+(J13-L13)+(N13-P13) -> 9 | D11: {=IF('Jornada 1'!G$76=1,INDEX('Jornada 1'!D$4:D$7,MATCH(4,'Jornada 1'!E$4:E$7,0)),INDEX('Jornada 1'!D$4:D$7,MATCH(3,'Jornada 1'!E$4:E$7,0)))} -> IAN DE LA BARQUERA | E11: =COUNTIF(C$11:C$14,">"&C11)+COUNTIF($C$11:C11,C11) -> 1 | F11: =D11 -> IAN DE LA BARQUERA | G11: VS | H11: =D13 -> ALONSO CISNEROS SANCHEZ | J11: =D11 -> IAN DE LA BARQUERA | K11: VS | L11: =D12 -> ELISA CAROLINA DIAZ LAGUNA | N11: =D11 -> IAN DE LA BARQUERA | O11: VS | P11: =D12 -> ELISA CAROLINA DIAZ LAGUNA | S11: =COUNTIF(T$4:T$27,">"&T11)+1 -> 8 | T11: =$C$39 -> 3 | U11: =$D$39 -> LUCAS CONTRERAS PADRÓN
C12: =(F13-H13)+(L13-J13)+(P13-N13) -> -1 | D12: {=IF('Jornada 1'!G$76=1,INDEX('Jornada 1'!D$12:D$15,MATCH(2,'Jornada 1'!E$12:E$15,0)),INDEX('Jornada 1'!D$4:D$7,MATCH(4,'Jornada 1'!E$4:E$7,0)))} -> ELISA CAROLINA DIAZ LAGUNA | E12: =COUNTIF(C$11:C$14,">"&C12)+COUNTIF($C$11:C12,C12) -> 2 | F12: =D12 -> ELISA CAROLINA DIAZ LAGUNA | H12: =D14 -> JESUS ANTONIO SEPULVEDA RODRIGUEZ | J12: =D13 -> ALONSO CISNEROS SANCHEZ | L12: =D14 -> JESUS ANTONIO SEPULVEDA RODRIGUEZ | N12: =D14 -> JESUS ANTONIO SEPULVEDA RODRIGUEZ | P12: =D13 -> ALONSO CISNEROS SANCHEZ | S12: =COUNTIF(T$4:T$27,">"&T12)+1 -> 8 | T12: =$C$41 -> 3 | U12: =$D$41 -> ADRIANA ESPINOZA SALDAÑA
C13: =(H13-F13)+(J13-L13)+(P13-N13) -> -5 | D13: {=IF('Jornada 1'!G$76=1,INDEX('Jornada 1'!D$12:D$15,MATCH(3,'Jornada 1'!E$12:E$15,0)),INDEX('Jornada 1'!D$20:D$23,MATCH(1,'Jornada 1'!E$20:E$23,0)))} -> ALONSO CISNEROS SANCHEZ | E13: =COUNTIF(C$11:C$14,">"&C13)+COUNTIF($C$11:C13,C13) -> 4 | F13: 4 | H13: 0 | J13: 4 | L13: 2 | N13: 4 | P13: 1 | S13: =COUNTIF(T$4:T$27,">"&T13)+1 -> 10 | T13: =$C$33 -> 2 | U13: =$D$33 -> JOSUÉ SANTIAGO PÉREZ MEDINA
C14: =(H13-F13)+(L13-J13)+(N13-P13) -> -3 | D14: {=IF('Jornada 1'!G$76=1,INDEX('Jornada 1'!D$20:D$23,MATCH(1,'Jornada 1'!E$20:E$23,0)),INDEX('Jornada 1'!D$20:D$23,MATCH(2,'Jornada 1'!E$20:E$23,0)))} -> JESUS ANTONIO SEPULVEDA RODRIGUEZ | E14: =COUNTIF(C$11:C$14,">"&C14)+COUNTIF($C$11:C14,C14) -> 3 | S14: =COUNTIF(T$4:T$27,">"&T14)+1 -> 11 | T14: =$C$20 -> 0 | U14: =$D$20 -> DIEGO PATRICIO FERNANDEZ VIERA
S15: =COUNTIF(T$4:T$27,">"&T15)+1 -> 12 | T15: =$C$12 -> -1 | U15: =$D$12 -> ELISA CAROLINA DIAZ LAGUNA
S16: =COUNTIF(T$4:T$27,">"&T16)+1 -> 12 | T16: =$C$27 -> -1 | U16: =$D$27 -> JOSE EMILIANO VAZQUEZ NUÑO
B17: Cancha 3 18:00 HS | C17: Puntos | D17: Jugadores | F17: Set 1 | J17: Set 2 | N17: Set 3 | S17: =COUNTIF(T$4:T$27,">"&T17)+1 -> 14 | T17: =$C$5 -> -3 | U17: =$D$5 -> MARIANO GOMEZ VUILLEUMIER
C18: =(F20-H20)+(J20-L20)+(N20-P20) -> 8 | D18: {=IF('Jornada 1'!G$76=1,INDEX('Jornada 1'!D$12:D$15,MATCH(4,'Jornada 1'!E$12:E$15,0)),INDEX('Jornada 1'!D$12:D$15,MATCH(3,'Jornada 1'!E$12:E$15,0)))} -> IKER FRANCISCO NORIEGA JIMENEZ | E18: =COUNTIF(C$18:C$21,">"&C18)+COUNTIF($C$18:C18,C18) -> 1 | F18: =D18 -> IKER FRANCISCO NORIEGA JIMENEZ | G18: VS | H18: =D20 -> DIEGO PATRICIO FERNANDEZ VIERA | J18: =D18 -> IKER FRANCISCO NORIEGA JIMENEZ | K18: VS | L18: =D19 -> EMILIO MATEO OLIVARES CORTÉS | N18: =D18 -> IKER FRANCISCO NORIEGA JIMENEZ | O18: VS | P18: =D19 -> EMILIO MATEO OLIVARES CORTÉS | S18: =COUNTIF(T$4:T$27,">"&T18)+1 -> 14 | T18: =$C$6 -> -3 | U18: =$D$6 -> NICOLAS MAXIMILIANO BRILL HERRERA
C19: =(F20-H20)+(L20-J20)+(P20-N20) -> -4 | D19: {=IF('Jornada 1'!G$76=1,INDEX('Jornada 1'!D$20:D$23,MATCH(2,'Jornada 1'!E$20:E$23,0)),INDEX('Jornada 1'!D$12:D$15,MATCH(4,'Jornada 1'!E$12:E$15,0)))} -> EMILIO MATEO OLIVARES CORTÉS | E19: =COUNTIF(C$18:C$21,">"&C19)+COUNTIF($C$18:C19,C19) -> 3 | F19: =D19 -> EMILIO MATEO OLIVARES CORTÉS | H19: =D21 -> MIGUEL ALCARAZ AMEZCUA | J19: =D20 -> DIEGO PATRICIO FERNANDEZ VIERA | L19: =D21 -> MIGUEL ALCARAZ AMEZCUA | N19: =D21 -> MIGUEL ALCARAZ AMEZCUA | P19: =D20 -> DIEGO PATRICIO FERNANDEZ VIERA | S19: =COUNTIF(T$4:T$27,">"&T19)+1 -> 14 | T19: =$C$14 -> -3 | U19: =$D$14 -> JESUS ANTONIO SEPULVEDA RODRIGUEZ
C20: =(H20-F20)+(J20-L20)+(P20-N20) -> 0 | D20: {=IF('Jornada 1'!G$76=1,INDEX('Jornada 1'!D$20:D$23,MATCH(3,'Jornada 1'!E$20:E$23,0)),INDEX('Jornada 1'!D$28:D$31,MATCH(1,'Jornada 1'!E$28:E$31,0)))} -> DIEGO PATRICIO FERNANDEZ VIERA | E20: =COUNTIF(C$18:C$21,">"&C20)+COUNTIF($C$18:C20,C20) -> 2 | F20: 4 | H20: 2 | J20: 4 | L20: 0 | N20: 4 | P20: 2 | S20: =COUNTIF(T$4:T$27,">"&T20)+1 -> 14 | T20: =$C$26 -> -3 | U20: =$D$26 -> CAMILO RODRIGUEZ PACHECO
C21: =(H20-F20)+(L20-J20)+(N20-P20) -> -4 | D21: {=IF('Jornada 1'!G$76=1,INDEX('Jornada 1'!D$28:D$31,MATCH(1,'Jornada 1'!E$28:E$31,0)),INDEX('Jornada 1'!D$28:D$31,MATCH(2,'Jornada 1'!E$28:E$31,0)))} -> MIGUEL ALCARAZ AMEZCUA | E21: =COUNTIF(C$18:C$21,">"&C21)+COUNTIF($C$18:C21,C21) -> 4 | S21: =COUNTIF(T$4:T$27,">"&T21)+1 -> 18 | T21: =$C$19 -> -4 | U21: =$D$19 -> EMILIO MATEO OLIVARES CORTÉS
S22: =COUNTIF(T$4:T$27,">"&T22)+1 -> 18 | T22: =$C$21 -> -4 | U22: =$D$21 -> MIGUEL ALCARAZ AMEZCUA
S23: =COUNTIF(T$4:T$27,">"&T23)+1 -> 20 | T23: =$C$7 -> -5 | U23: =$D$7 -> MARIANO NAVARRO LEAÑO
B24: Cancha 4 17:00 HS | C24: Puntos | D24: Jugadores | F24: Set 1 | J24: Set 2 | N24: Set 3 | S24: =COUNTIF(T$4:T$27,">"&T24)+1 -> 20 | T24: =$C$13 -> -5 | U24: =$D$13 -> ALONSO CISNEROS SANCHEZ
C25: =(F27-H27)+(J27-L27)+(N27-P27) -> -5 | D25: {=IF('Jornada 1'!G$76=1,INDEX('Jornada 1'!D$28:D$31,MATCH(2,'Jornada 1'!E$28:E$31,0)),INDEX('Jornada 1'!D$20:D$23,MATCH(4,'Jornada 1'!E$20:E$23,0)))} -> ALEJANDRO CAMARENA LOPEZ | E25: =COUNTIF(C$25:C$28,">"&C25)+COUNTIF($C$25:C25,C25) -> 4 | F25: =D25 -> ALEJANDRO CAMARENA LOPEZ | G25: VS | H25: =D27 -> JOSE EMILIANO VAZQUEZ NUÑO | J25: =D25 -> ALEJANDRO CAMARENA LOPEZ | K25: VS | L25: =D26 -> CAMILO RODRIGUEZ PACHECO | N25: =D25 -> ALEJANDRO CAMARENA LOPEZ | O25: VS | P25: =D26 -> CAMILO RODRIGUEZ PACHECO | S25: =COUNTIF(T$4:T$27,">"&T25)+1 -> 20 | T25: =$C$25 -> -5 | U25: =$D$25 -> ALEJANDRO CAMARENA LOPEZ
C26: =(F27-H27)+(L27-J27)+(P27-N27) -> -3 | D26: {=IF('Jornada 1'!G$76=1,INDEX('Jornada 1'!D$28:D$31,MATCH(3,'Jornada 1'!E$28:E$31,0)),INDEX('Jornada 1'!D$36:D$39,MATCH(1,'Jornada 1'!E$36:E$39,0)))} -> CAMILO RODRIGUEZ PACHECO | E26: =COUNTIF(C$25:C$28,">"&C26)+COUNTIF($C$25:C26,C26) -> 3 | F26: =D26 -> CAMILO RODRIGUEZ PACHECO | H26: =D28 -> MAURICIO LOZANO CASTILLERO | J26: =D27 -> JOSE EMILIANO VAZQUEZ NUÑO | L26: =D28 -> MAURICIO LOZANO CASTILLERO | N26: =D28 -> MAURICIO LOZANO CASTILLERO | P26: =D27 -> JOSE EMILIANO VAZQUEZ NUÑO | S26: =COUNTIF(T$4:T$27,">"&T26)+1 -> 23 | T26: =$C$35 -> -10 | U26: =$D$35 -> ALBERTO ROBLES ARMENTA
C27: =(H27-F27)+(J27-L27)+(P27-N27) -> -1 | D27: {=IF('Jornada 1'!G$76=1,INDEX('Jornada 1'!D$36:D$39,MATCH(1,'Jornada 1'!E$36:E$39,0)),INDEX('Jornada 1'!D$36:D$39,MATCH(2,'Jornada 1'!E$36:E$39,0)))} -> JOSE EMILIANO VAZQUEZ NUÑO | E27: =COUNTIF(C$25:C$28,">"&C27)+COUNTIF($C$25:C27,C27) -> 2 | F27: 0 | H27: 4 | J27: 1 | L27: 4 | N27: 4 | P27: 2 | S27: =COUNTIF(T$4:T$27,">"&T27)+1 -> 24 | T27: =$C$42 -> -11 | U27: =$D$42 -> CHRISTIAN ULISES ACOSTA LOMELI
C28: =(H27-F27)+(L27-J27)+(N27-P27) -> 9 | D28: MAURICIO LOZANO CASTILLERO | E28: =COUNTIF(C$25:C$28,">"&C28)+COUNTIF($C$25:C28,C28) -> 1
B31: Cancha 5 17:00 HS | C31: Puntos | D31: Jugadores | F31: Set 1 | J31: Set 2 | N31: Set 3
C32: =(F34-H34)+(J34-L34)+(N34-P34) -> 4 | D32: {=IF('Jornada 1'!G$76=1,INDEX('Jornada 1'!D$20:D$23,MATCH(4,'Jornada 1'!E$20:E$23,0)),INDEX('Jornada 1'!D$20:D$23,MATCH(3,'Jornada 1'!E$20:E$23,0)))} -> MAXIMILIANO HERNÁNDEZ OROZCO | E32: =COUNTIF(C$32:C$35,">"&C32)+COUNTIF($C$32:C32,C32) -> 1 | F32: =D32 -> MAXIMILIANO HERNÁNDEZ OROZCO | G32: VS | H32: =D34 -> ESTEFANO ROLANDO BECERRA HERNANDEZ | J32: =D32 -> MAXIMILIANO HERNÁNDEZ OROZCO | K32: VS | L32: =D33 -> JOSUÉ SANTIAGO PÉREZ MEDINA | N32: =D32 -> MAXIMILIANO HERNÁNDEZ OROZCO | O32: VS | P32: =D33 -> JOSUÉ SANTIAGO PÉREZ MEDINA
C33: =(F34-H34)+(L34-J34)+(P34-N34) -> 2 | D33: {=IF('Jornada 1'!G$76=1,INDEX('Jornada 1'!D$28:D$31,MATCH(4,'Jornada 1'!E$28:E$31,0)),INDEX('Jornada 1'!D$28:D$31,MATCH(3,'Jornada 1'!E$28:E$31,0)))} -> JOSUÉ SANTIAGO PÉREZ MEDINA | E33: =COUNTIF(C$32:C$35,">"&C33)+COUNTIF($C$32:C33,C33) -> 3 | F33: =D33 -> JOSUÉ SANTIAGO PÉREZ MEDINA | H33: =D35 -> ALBERTO ROBLES ARMENTA | J33: =D34 -> ESTEFANO ROLANDO BECERRA HERNANDEZ | L33: =D35 -> ALBERTO ROBLES ARMENTA | N33: =D35 -> ALBERTO ROBLES ARMENTA | P33: =D34 -> ESTEFANO ROLANDO BECERRA HERNANDEZ
C34: =(H34-F34)+(J34-L34)+(P34-N34) -> 4 | D34: {=IF('Jornada 1'!G$76=1,INDEX('Jornada 1'!D$36:D$39,MATCH(2,'Jornada 1'!E$36:E$39,0)),INDEX('Jornada 1'!D$28:D$31,MATCH(4,'Jornada 1'!E$28:E$31,0)))} -> ESTEFANO ROLANDO BECERRA HERNANDEZ | E34: =COUNTIF(C$32:C$35,">"&C34)+COUNTIF($C$32:C34,C34) -> 2 | F34: 4 | H34: 1 | J34: 4 | L34: 0 | N34: 1 | P34: 4
A35: BAJO | C35: =(H34-F34)+(L34-J34)+(N34-P34) -> -10 | D35: {=IF('Jornada 1'!G$76=1,INDEX('Jornada 1'!D$36:D$39,MATCH(3,'Jornada 1'!E$36:E$39,0)),INDEX('Jornada 1'!D$44:D$47,MATCH(1,'Jornada 1'!E$44:E$47,0)))} -> ALBERTO ROBLES ARMENTA | E35: =COUNTIF(C$32:C$35,">"&C35)+COUNTIF($C$32:C35,C35) -> 4
B38: Cancha 6 17:00 HS | C38: Puntos | D38: Jugadores | F38: Set 1 | J38: Set 2 | N38: Set 3
C39: =(F41-H41)+(J41-L41)+(N41-P41) -> 3 | D39: {=IF('Jornada 1'!G$76=1,INDEX('Jornada 1'!D$36:D$39,MATCH(4,'Jornada 1'!E$36:E$39,0)),INDEX('Jornada 1'!D$36:D$39,MATCH(3,'Jornada 1'!E$36:E$39,0)))} -> LUCAS CONTRERAS PADRÓN | E39: =COUNTIF(C$39:C$42,">"&C39)+COUNTIF($C$39:C39,C39) -> 2 | F39: =D39 -> LUCAS CONTRERAS PADRÓN | G39: VS | H39: =D41 -> ADRIANA ESPINOZA SALDAÑA | J39: =D39 -> LUCAS CONTRERAS PADRÓN | K39: VS | L39: =D40 -> LEO LUCERO KOLB | N39: =D39 -> LUCAS CONTRERAS PADRÓN | O39: VS | P39: =D40 -> LEO LUCERO KOLB
C40: =(F41-H41)+(L41-J41)+(P41-N41) -> 5 | D40: {=IF('Jornada 1'!G$76=1,INDEX('Jornada 1'!D$44:D$47,MATCH(1,'Jornada 1'!E$44:E$47,0)),INDEX('Jornada 1'!D$44:D$47,MATCH(2,'Jornada 1'!E$44:E$47,0)))} -> LEO LUCERO KOLB | E40: =COUNTIF(C$39:C$42,">"&C40)+COUNTIF($C$39:C40,C40) -> 1 | F40: =D40 -> LEO LUCERO KOLB | H40: =D42 -> CHRISTIAN ULISES ACOSTA LOMELI | J40: =D41 -> ADRIANA ESPINOZA SALDAÑA | L40: =D42 -> CHRISTIAN ULISES ACOSTA LOMELI | N40: =D42 -> CHRISTIAN ULISES ACOSTA LOMELI | P40: =D41 -> ADRIANA ESPINOZA SALDAÑA
C41: =(H41-F41)+(J41-L41)+(P41-N41) -> 3 | D41: {=IF('Jornada 1'!G$76=1,INDEX('Jornada 1'!D$44:D$47,MATCH(2,'Jornada 1'!E$44:E$47,0)),INDEX('Jornada 1'!D$36:D$39,MATCH(4,'Jornada 1'!E$36:E$39,0)))} -> ADRIANA ESPINOZA SALDAÑA | E41: =COUNTIF(C$39:C$42,">"&C41)+COUNTIF($C$39:C41,C41) -> 3 | F41: 4 | H41: 0 | J41: 4 | L41: 1 | N41: 0 | P41: 4
C42: =(H41-F41)+(L41-J41)+(N41-P41) -> -11 | D42: {=INDEX('Jornada 1'!D$40:D$47,MATCH(4,'Jornada 1'!E$40:E$47,0))} -> CHRISTIAN ULISES ACOSTA LOMELI | E42: =COUNTIF(C$39:C$42,">"&C42)+COUNTIF($C$39:C42,C42) -> 4
B45: Cancha 7 | C45: Puntos | D45: Jugadores | F45: Set 1 | J45: Set 2 | N45: Set 3
C46: =(F48-H48)+(J48-L48)+(N48-P48) -> 0 | D46: Jugador 1 | F46: =D46 -> Jugador 1 | G46: VS | H46: =D48 -> Jugador 3 | J46: =D46 -> Jugador 1 | K46: VS | L46: =D47 -> Jugador 2 | N46: =D46 -> Jugador 1 | O46: VS | P46: =D47 -> Jugador 2
...

Sheet Jornada 3
F1: CANCHA 1
S2: Ranking de la jornada
B3: Cancha 1 18:00 HS | C3: Puntos | D3: Jugadores | F3: Set 1 | J3: Set 2 | N3: Set 3 | S3: Ranking | T3: Puntos | U3: Jugadores
C4: =(F6-H6)+(J6-L6)+(N6-P6) -> 0 | D4: =INDEX('Jornada 2 (1)'!D$4:D$7, MATCH(1,'Jornada 2 (1)'!E$4:E$7,0)) -> MAURICIO ALEJANDRO BAUTISTA | E4: =COUNTIF(C$4:C$7,">"&C4)+COUNTIF($C$4:C4,C4) -> 1 | F4: =D4 -> MAURICIO ALEJANDRO BAUTISTA | G4: VS | H4: =D6 -> IAN DE LA BARQUERA | J4: =D4 -> MAURICIO ALEJANDRO BAUTISTA | K4: VS | L4: =D5 -> MARIANO GOMEZ VUILLEUMIER | N4: =D4 -> MAURICIO ALEJANDRO BAUTISTA | O4: VS | P4: =D5 -> MARIANO GOMEZ VUILLEUMIER | S4: =COUNTIF(T$4:T$27,">"&T4)+1 -> 1 | T4: =$C$4 -> 0 | U4: =$D$4 -> MAURICIO ALEJANDRO BAUTISTA
C5: =(F6-H6)+(L6-J6)+(P6-N6) -> 0 | D5: =INDEX('Jornada 2 (1)'!D$4:D$7, MATCH(2,'Jornada 2 (1)'!E$4:E$7,0)) -> MARIANO GOMEZ VUILLEUMIER | E5: =COUNTIF(C$4:C$7,">"&C5)+COUNTIF($C$4:C5,C5) -> 2 | F5: =D5 -> MARIANO GOMEZ VUILLEUMIER | H5: =D7 -> ELISA CAROLINA DIAZ LAGUNA | J5: =D6 -> IAN DE LA BARQUERA | L5: =D7 -> ELISA CAROLINA DIAZ LAGUNA | N5: =D7 -> ELISA CAROLINA DIAZ LAGUNA | P5: =D6 -> IAN DE LA BARQUERA | S5: =COUNTIF(T$4:T$27,">"&T5)+1 -> 1 | T5: =$C$11 -> 0 | U5: =$D$11 -> NICOLAS MAXIMILIANO BRILL HERRERA
C6: =(H6-F6)+(J6-L6)+(P6-N6) -> 0 | D6: =IF('Jornada 2 (1)'!G70=1,INDEX('Jornada 2 (1)'!D$4:D$7,MATCH(3,'Jornada 2 (1)'!E$4:E$7,0)),INDEX('Jornada 2 (1)'!D$11:D$14,MATCH(1,'Jornada 2 (1)'!E$11:E$14,0))) -> IAN DE LA BARQUERA | E6: =COUNTIF(C$4:C$7,">"&C6)+COUNTIF($C$4:C6,C6) -> 3 | S6: =COUNTIF(T$4:T$27,">"&T6)+1 -> 1 | T6: =$C$28 -> 0 | U6: =$D$28 -> ESTEFANO ROLANDO BECERRA HERNANDEZ
C7: =(H6-F6)+(L6-J6)+(N6-P6) -> 0 | D7: =IF('Jornada 2 (1)'!G70=1,INDEX('Jornada 2 (1)'!D$11:D$14,MATCH(1,'Jornada 2 (1)'!E$11:E$14,0)),INDEX('Jornada 2 (1)'!D$11:D$14,MATCH(2,'Jornada 2 (1)'!E$11:E$14,0))) -> ELISA CAROLINA DIAZ LAGUNA | E7: =COUNTIF(C$4:C$7,">"&C7)+COUNTIF($C$4:C7,C7) -> 4 | S7: =COUNTIF(T$4:T$27,">"&T7)+1 -> 1 | T7: =$C$18 -> 0 | U7: =$D$18 -> JESUS ANTONIO SEPULVEDA RODRIGUEZ
S8: =COUNTIF(T$4:T$27,">"&T8)+1 -> 1 | T8: =$C$40 -> 0 | U8: =$D$40 -> ALBERTO ROBLES ARMENTA
S9: =COUNTIF(T$4:T$27,">"&T9)+1 -> 1 | T9: =$C$32 -> 0 | U9: =$D$32 -> CAMILO RODRIGUEZ PACHECO
B10: Cancha 2 18:00 HS | C10: Puntos | D10: Jugadores | F10: Set 1 | J10: Set 2 | N10: Set 3 | S10: =COUNTIF(T$4:T$27,">"&T10)+1 -> 1 | T10: =$C$34 -> 0 | U10: =$D$34 -> LEO LUCERO KOLB
C11: =(F13-H13)+(J13-L13)+(N13-P13) -> 0 | D11: =IF('Jornada 2 (1)'!G$70=1,INDEX('Jornada 2 (1)'!D$4:D$7,MATCH(4,'Jornada 2 (1)'!E$4:E$7,0)),INDEX('Jornada 2 (1)'!D$4:D$7,MATCH(3,'Jornada 2 (1)'!E$4:E$7,0))) -> NICOLAS MAXIMILIANO BRILL HERRERA | E11: =COUNTIF(C$11:C$14,">"&C11)+COUNTIF($C$11:C11,C11) -> 1 | F11: =D11 -> NICOLAS MAXIMILIANO BRILL HERRERA | G11: VS | H11: =D13 -> IKER FRANCISCO NORIEGA JIMENEZ | J11: =D11 -> NICOLAS MAXIMILIANO BRILL HERRERA | K11: VS | L11: =D12 -> MARIANO NAVARRO LEAÑO | N11: =D11 -> NICOLAS MAXIMILIANO BRILL HERRERA | O11: VS | P11: =D12 -> MARIANO NAVARRO LEAÑO | S11: =COUNTIF(T$4:T$27,">"&T11)+1 -> 1 | T11: =$C$39 -> 0 | U11: =$D$39 -> JOSUÉ SANTIAGO PÉREZ MEDINA
C12: =(F13-H13)+(L13-J13)+(P13-N13) -> 0 | D12: =IF('Jornada 2 (1)'!G$70=1,INDEX('Jornada 2 (1)'!D$11:D$14,MATCH(2,'Jornada 2 (1)'!E$11:E$14,0)),INDEX('Jornada 2 (1)'!D$4:D$7,MATCH(4,'Jornada 2 (1)'!E$4:E$7,0))) -> MARIANO NAVARRO LEAÑO | E12: =COUNTIF(C$11:C$14,">"&C12)+COUNTIF($C$11:C12,C12) -> 2 | F12: =D12 -> MARIANO NAVARRO LEAÑO | H12: =D14 -> DIEGO PATRICIO FERNANDEZ VIERA | J12: =D13 -> IKER FRANCISCO NORIEGA JIMENEZ | L12: =D14 -> DIEGO PATRICIO FERNANDEZ VIERA | N12: =D14 -> DIEGO PATRICIO FERNANDEZ VIERA | P12: =D13 -> IKER FRANCISCO NORIEGA JIMENEZ | S12: =COUNTIF(T$4:T$27,">"&T12)+1 -> 1 | T12: =$C$41 -> 0 | U12: =$D$41 -> ADRIANA ESPINOZA SALDAÑA
C13: =(H13-F13)+(J13-L13)+(P13-N13) -> 0 | D13: =IF('Jornada 2 (1)'!G$70=1,INDEX('Jornada 2 (1)'!D$11:D$14,MATCH(3,'Jornada 2 (1)'!E$11:E$14,0)),INDEX('Jornada 2 (1)'!D$18:D$21,MATCH(1,'Jornada 2 (1)'!E$18:E$21,0))) -> IKER FRANCISCO NORIEGA JIMENEZ | E13: =COUNTIF(C$11:C$14,">"&C13)+COUNTIF($C$11:C13,C13) -> 3 | S13: =COUNTIF(T$4:T$27,">"&T13)+1 -> 1 | T13: =$C$33 -> 0 | U13: =$D$33 -> ALEJANDRO CAMARENA LOPEZ
C14: =(H13-F13)+(L13-J13)+(N13-P13) -> 0 | D14: =IF('Jornada 2 (1)'!G$70=1,INDEX('Jornada 2 (1)'!D$18:D$21,MATCH(1,'Jornada 2 (1)'!E$18:E$21,0)),INDEX('Jornada 2 (1)'!D$18:D$21,MATCH(2,'Jornada 2 (1)'!E$18:E$21,0))) -> DIEGO PATRICIO FERNANDEZ VIERA | E14: =COUNTIF(C$11:C$14,">"&C14)+COUNTIF($C$11:C14,C14) -> 4 | S14: =COUNTIF(T$4:T$27,">"&T14)+1 -> 1 | T14: =$C$20 -> 0 | U14: =$D$20 -> MAURICIO LOZANO CASTILLERO
S15: =COUNTIF(T$4:T$27,">"&T15)+1 -> 1 | T15: =$C$12 -> 0 | U15: =$D$12 -> MARIANO NAVARRO LEAÑO
S16: =COUNTIF(T$4:T$27,">"&T16)+1 -> 1 | T16: =$C$27 -> 0 | U16: =$D$27 -> MAXIMILIANO HERNÁNDEZ OROZCO
B17: Cancha 3 18:00 HS | C17: Puntos | D17: Jugadores | F17: Set 1 | J17: Set 2 | N17: Set 3 | S17: =COUNTIF(T$4:T$27,">"&T17)+1 -> 1 | T17: =$C$5 -> 0 | U17: =$D$5 -> MARIANO GOMEZ VUILLEUMIER
C18: =(F20-H20)+(J20-L20)+(N20-P20) -> 0 | D18: =IF('Jornada 2 (1)'!G$70=1,INDEX('Jornada 2 (1)'!D$11:D$14,MATCH(4,'Jornada 2 (1)'!E$11:E$14,0)),INDEX('Jornada 2 (1)'!D$11:D$14,MATCH(3,'Jornada 2 (1)'!E$11:E$14,0))) -> JESUS ANTONIO SEPULVEDA RODRIGUEZ | E18: =COUNTIF(C$18:C$21,">"&C18)+COUNTIF($C$18:C18,C18) -> 1 | F18: =D18 -> JESUS ANTONIO SEPULVEDA RODRIGUEZ | G18: VS | H18: =D20 -> MAURICIO LOZANO CASTILLERO | J18: =D18 -> JESUS ANTONIO SEPULVEDA RODRIGUEZ | K18: VS | L18: =D19 -> ALONSO CISNEROS SANCHEZ | N18: =D18 -> JESUS ANTONIO SEPULVEDA RODRIGUEZ | O18: VS | P18: =D19 -> ALONSO CISNEROS SANCHEZ | S18: =COUNTIF(T$4:T$27,">"&T18)+1 -> 1 | T18: =$C$6 -> 0 | U18: =$D$6 -> IAN DE LA BARQUERA
C19: =(F20-H20)+(L20-J20)+(P20-N20) -> 0 | D19: =IF('Jornada 2 (1)'!G$70=1,INDEX('Jornada 2 (1)'!D$18:D$21,MATCH(2,'Jornada 2 (1)'!E$18:E$21,0)),INDEX('Jornada 2 (1)'!D$11:D$14,MATCH(4,'Jornada 2 (1)'!E$11:E$14,0))) -> ALONSO CISNEROS SANCHEZ | E19: =COUNTIF(C$18:C$21,">"&C19)+COUNTIF($C$18:C19,C19) -> 2 | F19: =D19 -> ALONSO CISNEROS SANCHEZ | H19: =D21 -> JOSE EMILIANO VAZQUEZ NUÑO | J19: =D20 -> MAURICIO LOZANO CASTILLERO | L19: =D21 -> JOSE EMILIANO VAZQUEZ NUÑO | N19: =D21 -> JOSE EMILIANO VAZQUEZ NUÑO | P19: =D20 -> MAURICIO LOZANO CASTILLERO | S19: =COUNTIF(T$4:T$27,">"&T19)+1 -> 1 | T19: =$C$14 -> 0 | U19: =$D$14 -> DIEGO PATRICIO FERNANDEZ VIERA
C20: =(H20-F20)+(J20-L20)+(P20-N20) -> 0 | D20: =IF('Jornada 2 (1)'!G$70=1,INDEX('Jornada 2 (1)'!D$18:D$21,MATCH(3,'Jornada 2 (1)'!E$18:E$21,0)),INDEX('Jornada 2 (1)'!D$25:D$28,MATCH(1,'Jornada 2 (1)'!E$25:E$28,0))) -> MAURICIO LOZANO CASTILLERO | E20: =COUNTIF(C$18:C$21,">"&C20)+COUNTIF($C$18:C20,C20) -> 3 | S20: =COUNTIF(T$4:T$27,">"&T20)+1 -> 1 | T20: =$C$26 -> 0 | U20: =$D$26 -> MIGUEL ALCARAZ AMEZCUA
C21: =(H20-F20)+(L20-J20)+(N20-P20) -> 0 | D21: =IF('Jornada 2 (1)'!G$70=1,INDEX('Jornada 2 (1)'!D$25:D$28,MATCH(1,'Jornada 2 (1)'!E$25:E$28,0)),INDEX('Jornada 2 (1)'!D$25:D$28,MATCH(2,'Jornada 2 (1)'!E$25:E$28,0))) -> JOSE EMILIANO VAZQUEZ NUÑO | E21: =COUNTIF(C$18:C$21,">"&C21)+COUNTIF($C$18:C21,C21) -> 4 | S21: =COUNTIF(T$4:T$27,">"&T21)+1 -> 1 | T21: =$C$19 -> 0 | U21: =$D$19 -> ALONSO CISNEROS SANCHEZ
S22: =COUNTIF(T$4:T$27,">"&T22)+1 -> 1 | T22: =$C$21 -> 0 | U22: =$D$21 -> JOSE EMILIANO VAZQUEZ NUÑO
S23: =COUNTIF(T$4:T$27,">"&T23)+1 -> 1 | T23: =$C$7 -> 0 | U23: =$D$7 -> ELISA CAROLINA DIAZ LAGUNA
B24: Cancha 4 17:00 HS | C24: Puntos | D24: Jugadores | F24: Set 1 | J24: Set 2 | N24: Set 3 | S24: =COUNTIF(T$4:T$27,">"&T24)+1 -> 1 | T24: =$C$13 -> 0 | U24: =$D$13 -> IKER FRANCISCO NORIEGA JIMENEZ
C25: =(F27-H27)+(J27-L27)+(N27-P27) -> 0 | D25: =IF('Jornada 2 (1)'!G$70=1,INDEX('Jornada 2 (1)'!D$18:D$21,MATCH(4,'Jornada 2 (1)'!E$18:E$21,0)),INDEX('Jornada 2 (1)'!D$18:D$21,MATCH(3,'Jornada 2 (1)'!E$18:E$21,0))) -> EMILIO MATEO OLIVARES CORTÉS | E25: =COUNTIF(C$25:C$28,">"&C25)+COUNTIF($C$25:C25,C25) -> 1 | F25: =D25 -> EMILIO MATEO OLIVARES CORTÉS | G25: VS | H25: =D27 -> MAXIMILIANO HERNÁNDEZ OROZCO | J25: =D25 -> EMILIO MATEO OLIVARES CORTÉS | K25: VS | L25: =D26 -> MIGUEL ALCARAZ AMEZCUA | N25: =D25 -> EMILIO MATEO OLIVARES CORTÉS | O25: VS | P25: =D26 -> MIGUEL ALCARAZ AMEZCUA | S25: =COUNTIF(T$4:T$27,">"&T25)+1 -> 1 | T25: =$C$25 -> 0 | U25: =$D$25 -> EMILIO MATEO OLIVARES CORTÉS
C26: =(F27-H27)+(L27-J27)+(P27-N27) -> 0 | D26: =IF('Jornada 2 (1)'!G$70=1,INDEX('Jornada 2 (1)'!D$25:D$28,MATCH(2,'Jornada 2 (1)'!E$25:E$28,0)),INDEX('Jornada 2 (1)'!D$18:D$21,MATCH(4,'Jornada 2 (1)'!E$18:E$21,0))) -> MIGUEL ALCARAZ AMEZCUA | E26: =COUNTIF(C$25:C$28,">"&C26)+COUNTIF($C$25:C26,C26) -> 2 | F26: =D26 -> MIGUEL ALCARAZ AMEZCUA | H26: =D28 -> ESTEFANO ROLANDO BECERRA HERNANDEZ | J26: =D27 -> MAXIMILIANO HERNÁNDEZ OROZCO | L26: =D28 -> ESTEFANO ROLANDO BECERRA HERNANDEZ | N26: =D28 -> ESTEFANO ROLANDO BECERRA HERNANDEZ | P26: =D27 -> MAXIMILIANO HERNÁNDEZ OROZCO | S26: =COUNTIF(T$4:T$27,">"&T26)+1 -> 1 | T26: =$C$35 -> 0 | U26: =$D$35 -> LUCAS CONTRERAS PADRÓN
C27: =(H27-F27)+(J27-L27)+(P27-N27) -> 0 | D27: =IF('Jornada 2 (1)'!G$70=1,INDEX('Jornada 2 (1)'!D$25:D$28,MATCH(3,'Jornada 2 (1)'!E$25:E$28,0)),INDEX('Jornada 2 (1)'!D$32:D$35,MATCH(1,'Jornada 2 (1)'!E$32:E$35,0))) -> MAXIMILIANO HERNÁNDEZ OROZCO | E27: =COUNTIF(C$25:C$28,">"&C27)+COUNTIF($C$25:C27,C27) -> 3 | S27: =COUNTIF(T$4:T$27,">"&T27)+1 -> 1 | T27: =$C$42 -> 0 | U27: =$D$42 -> CHRISTIAN ULISES ACOSTA LOMELI
C28: =(H27-F27)+(L27-J27)+(N27-P27) -> 0 | D28: =IF('Jornada 2 (1)'!G$70=1,INDEX('Jornada 2 (1)'!D$32:D$35,MATCH(1,'Jornada 2 (1)'!E$32:E$35,0)),INDEX('Jornada 2 (1)'!D$32:D$35,MATCH(2,'Jornada 2 (1)'!E$32:E$35,0))) -> ESTEFANO ROLANDO BECERRA HERNANDEZ | E28: =COUNTIF(C$25:C$28,">"&C28)+COUNTIF($C$25:C28,C28) -> 4
B31: Cancha 5 17:00 HS | C31: Puntos | D31: Jugadores | F31: Set 1 | J31: Set 2 | N31: Set 3
C32: =(F34-H34)+(J34-L34)+(N34-P34) -> 0 | D32: =IF('Jornada 2 (1)'!G$70=1,INDEX('Jornada 2 (1)'!D$25:D$28,MATCH(4,'Jornada 2 (1)'!E$25:E$28,0)),INDEX('Jornada 2 (1)'!D$25:D$28,MATCH(3,'Jornada 2 (1)'!E$25:E$28,0))) -> CAMILO RODRIGUEZ PACHECO | E32: =COUNTIF(C$32:C$35,">"&C32)+COUNTIF($C$32:C32,C32) -> 1 | F32: =D32 -> CAMILO RODRIGUEZ PACHECO | G32: VS | H32: =D34 -> LEO LUCERO KOLB | J32: =D32 -> CAMILO RODRIGUEZ PACHECO | K32: VS | L32: =D33 -> ALEJANDRO CAMARENA LOPEZ | N32: =D32 -> CAMILO RODRIGUEZ PACHECO | O32: VS | P32: =D33 -> ALEJANDRO CAMARENA LOPEZ
C33: =(F34-H34)+(L34-J34)+(P34-N34) -> 0 | D33: =IF('Jornada 2 (1)'!G$70=1,INDEX('Jornada 2 (1)'!D$32:D$35,MATCH(2,'Jornada 2 (1)'!E$32:E$35,0)),INDEX('Jornada 2 (1)'!D$25:D$28,MATCH(4,'Jornada 2 (1)'!E$25:E$28,0))) -> ALEJANDRO CAMARENA LOPEZ | E33: =COUNTIF(C$32:C$35,">"&C33)+COUNTIF($C$32:C33,C33) -> 2 | F33: =D33 -> ALEJANDRO CAMARENA LOPEZ | H33: =D35 -> LUCAS CONTRERAS PADRÓN | J33: =D34 -> LEO LUCERO KOLB | L33: =D35 -> LUCAS CONTRERAS PADRÓN | N33: =D35 -> LUCAS CONTRERAS PADRÓN | P33: =D34 -> LEO LUCERO KOLB
C34: =(H34-F34)+(J34-L34)+(P34-N34) -> 0 | D34: =IF('Jornada 2 (1)'!G$70=1,INDEX('Jornada 2 (1)'!D$32:D$35,MATCH(3,'Jornada 2 (1)'!E$32:E$35,0)),INDEX('Jornada 2 (1)'!D$39:D$42,MATCH(1,'Jornada 2 (1)'!E$39:E$42,0))) -> LEO LUCERO KOLB | E34: =COUNTIF(C$32:C$35,">"&C34)+COUNTIF($C$32:C34,C34) -> 3
A35: BAJO | C35: =(H34-F34)+(L34-J34)+(N34-P34) -> 0 | D35: =IF('Jornada 2 (1)'!G$70=1,INDEX('Jornada 2 (1)'!D$39:D$42,MATCH(1,'Jornada 2 (1)'!E$39:E$42,0)),INDEX('Jornada 2 (1)'!D$39:D$42,MATCH(2,'Jornada 2 (1)'!E$39:E$42,0))) -> LUCAS CONTRERAS PADRÓN | E35: =COUNTIF(C$32:C$35,">"&C35)+COUNTIF($C$32:C35,C35) -> 4
B38: Cancha 6 17:00 HS | C38: Puntos | D38: Jugadores | F38: Set 1 | J38: Set 2 | N38: Set 3
C39: =(F41-H41)+(J41-L41)+(N41-P41) -> 0 | D39: =IF('Jornada 2 (1)'!G$70=1,INDEX('Jornada 2 (1)'!D$32:D$35,MATCH(4,'Jornada 2 (1)'!E$32:E$35,0)),INDEX('Jornada 2 (1)'!D$32:D$35,MATCH(3,'Jornada 2 (1)'!E$32:E$35,0))) -> JOSUÉ SANTIAGO PÉREZ MEDINA | E39: =COUNTIF(C$39:C$42,">"&C39)+COUNTIF($C$39:C39,C39) -> 1 | F39: =D39 -> JOSUÉ SANTIAGO PÉREZ MEDINA | G39: VS | H39: =D41 -> ADRIANA ESPINOZA SALDAÑA | J39: =D39 -> JOSUÉ SANTIAGO PÉREZ MEDINA | K39: VS | L39: =D40 -> ALBERTO ROBLES ARMENTA | N39: =D39 -> JOSUÉ SANTIAGO PÉREZ MEDINA | O39: VS | P39: =D40 -> ALBERTO ROBLES ARMENTA
C40: =(F41-H41)+(L41-J41)+(P41-N41) -> 0 | D40: =IF('Jornada 2 (1)'!G$70=1,INDEX('Jornada 2 (1)'!D$39:D$42,MATCH(2,'Jornada 2 (1)'!E$39:E$42,0)),INDEX('Jornada 2 (1)'!D$32:D$35,MATCH(4,'Jornada 2 (1)'!E$32:E$35,0))) -> ALBERTO ROBLES ARMENTA | E40: =COUNTIF(C$39:C$42,">"&C40)+COUNTIF($C$39:C40,C40) -> 2 | F40: =D40 -> ALBERTO ROBLES ARMENTA | H40: =D42 -> CHRISTIAN ULISES ACOSTA LOMELI | J40: =D41 -> ADRIANA ESPINOZA SALDAÑA | L40: =D42 -> CHRISTIAN ULISES ACOSTA LOMELI | N40: =D42 -> CHRISTIAN ULISES ACOSTA LOMELI | P40: =D41 -> ADRIANA ESPINOZA SALDAÑA
C41: =(H41-F41)+(J41-L41)+(P41-N41) -> 0 | D41: =INDEX('Jornada 2 (1)'!D$39:D$42,MATCH(3,'Jornada 2 (1)'!E$39:E$42,0)) -> ADRIANA ESPINOZA SALDAÑA | E41: =COUNTIF(C$39:C$42,">"&C41)+COUNTIF($C$39:C41,C41) -> 3
C42: =(H41-F41)+(L41-J41)+(N41-P41) -> 0 | D42: =INDEX('Jornada 2 (1)'!D$39:D$42,MATCH(4,'Jornada 2 (1)'!E$39:E$42,0)) -> CHRISTIAN ULISES ACOSTA LOMELI | E42: =COUNTIF(C$39:C$42,">"&C42)+COUNTIF($C$39:C42,C42) -> 4
B45: Cancha 7 | C45: Puntos | D45: Jugadores | F45: Set 1 | J45: Set 2 | N45: Set 3
C46: =(F48-H48)+(J48-L48)+(N48-P48) -> 0 | D46: Jugador 1 | F46: =D46 -> Jugador 1 | G46: VS | H46: =D48 -> Jugador 3 | J46: =D46 -> Jugador 1 | K46: VS | L46: =D47 -> Jugador 2 | N46: =D46 -> Jugador 1 | O46: VS | P46: =D47 -> Jugador 2
...

Sheet Jornada 4
F1: CANCHA 1
S2: Ranking de la jornada
B3: Cancha 1 18:00 HS | C3: Puntos | D3: Jugadores | F3: Set 1 | J3: Set 2 | N3: Set 3 | S3: Ranking | T3: Puntos | U3: Jugadores
C4: =(F6-H6)+(J6-L6)+(N6-P6) -> 0 | D4: =INDEX('Jornada 3'!D$4:D$7, MATCH(1,'Jornada 3'!E$4:E$7,0)) -> MAURICIO ALEJANDRO BAUTISTA | E4: =COUNTIF(C$4:C$7,">"&C4)+COUNTIF($C$4:C4,C4) -> 1 | F4: =D4 -> MAURICIO ALEJANDRO BAUTISTA | G4: VS | H4: =D6 -> NICOLAS MAXIMILIANO BRILL HERRERA | J4: =D4 -> MAURICIO ALEJANDRO BAUTISTA | K4: VS | L4: =D5 -> MARIANO GOMEZ VUILLEUMIER | N4: =D4 -> MAURICIO ALEJANDRO BAUTISTA | O4: VS | P4: =D5 -> MARIANO GOMEZ VUILLEUMIER | S4: =COUNTIF(T$4:T$27,">"&T4)+1 -> 1 | T4: =$C$4 -> 0 | U4: =$D$4 -> MAURICIO ALEJANDRO BAUTISTA
C5: =(F6-H6)+(L6-J6)+(P6-N6) -> 0 | D5: =INDEX('Jornada 3'!D$4:D$7, MATCH(2,'Jornada 3'!E$4:E$7,0)) -> MARIANO GOMEZ VUILLEUMIER | E5: =COUNTIF(C$4:C$7,">"&C5)+COUNTIF($C$4:C5,C5) -> 2 | F5: =D5 -> MARIANO GOMEZ VUILLEUMIER | H5: =D7 -> MARIANO NAVARRO LEAÑO | J5: =D6 -> NICOLAS MAXIMILIANO BRILL HERRERA | L5: =D7 -> MARIANO NAVARRO LEAÑO | N5: =D7 -> MARIANO NAVARRO LEAÑO | P5: =D6 -> NICOLAS MAXIMILIANO BRILL HERRERA | S5: =COUNTIF(T$4:T$27,">"&T5)+1 -> 1 | T5: =$C$11 -> 0 | U5: =$D$11 -> IAN DE LA BARQUERA
C6: =(H6-F6)+(J6-L6)+(P6-N6) -> 0 | D6: =IF('Jornada 3'!G70=1,INDEX('Jornada 3'!D$4:D$7,MATCH(3,'Jornada 3'!E$4:E$7,0)),INDEX('Jornada 3'!D$11:D$14,MATCH(1,'Jornada 3'!E$11:E$14,0))) -> NICOLAS MAXIMILIANO BRILL HERRERA | E6: =COUNTIF(C$4:C$7,">"&C6)+COUNTIF($C$4:C6,C6) -> 3 | S6: =COUNTIF(T$4:T$27,">"&T6)+1 -> 1 | T6: =$C$28 -> 0 | U6: =$D$28 -> ALEJANDRO CAMARENA LOPEZ
C7: =(H6-F6)+(L6-J6)+(N6-P6) -> 0 | D7: =IF('Jornada 3'!G70=1,INDEX('Jornada 3'!D$11:D$14,MATCH(1,'Jornada 3'!E$11:E$14,0)),INDEX('Jornada 3'!D$11:D$14,MATCH(2,'Jornada 3'!E$11:E$14,0))) -> MARIANO NAVARRO LEAÑO | E7: =COUNTIF(C$4:C$7,">"&C7)+COUNTIF($C$4:C7,C7) -> 4 | S7: =COUNTIF(T$4:T$27,">"&T7)+1 -> 1 | T7: =$C$18 -> 0 | U7: =$D$18 -> IKER FRANCISCO NORIEGA JIMENEZ
S8: =COUNTIF(T$4:T$27,">"&T8)+1 -> 1 | T8: =$C$40 -> 0 | U8: =$D$40 -> LUCAS CONTRERAS PADRÓN
S9: =COUNTIF(T$4:T$27,">"&T9)+1 -> 1 | T9: =$C$32 -> 0 | U9: =$D$32 -> MAXIMILIANO HERNÁNDEZ OROZCO
B10: Cancha 2 18:00 HS | C10: Puntos | D10: Jugadores | F10: Set 1 | J10: Set 2 | N10: Set 3 | S10: =COUNTIF(T$4:T$27,">"&T10)+1 -> 1 | T10: =$C$34 -> 0 | U10: =$D$34 -> JOSUÉ SANTIAGO PÉREZ MEDINA
C11: =(F13-H13)+(J13-L13)+(N13-P13) -> 0 | D11: =IF('Jornada 3'!G$70=1,INDEX('Jornada 3'!D$4:D$7,MATCH(4,'Jornada 3'!E$4:E$7,0)),INDEX('Jornada 3'!D$4:D$7,MATCH(3,'Jornada 3'!E$4:E$7,0))) -> IAN DE LA BARQUERA | E11: =COUNTIF(C$11:C$14,">"&C11)+COUNTIF($C$11:C11,C11) -> 1 | F11: =D11 -> IAN DE LA BARQUERA | G11: VS | H11: =D13 -> JESUS ANTONIO SEPULVEDA RODRIGUEZ | J11: =D11 -> IAN DE LA BARQUERA | K11: VS | L11: =D12 -> ELISA CAROLINA DIAZ LAGUNA | N11: =D11 -> IAN DE LA BARQUERA | O11: VS | P11: =D12 -> ELISA CAROLINA DIAZ LAGUNA | S11: =COUNTIF(T$4:T$27,">"&T11)+1 -> 1 | T11: =$C$39 -> 0 | U11: =$D$39 -> LEO LUCERO KOLB
C12: =(F13-H13)+(L13-J13)+(P13-N13) -> 0 | D12: =IF('Jornada 3'!G$70=1,INDEX('Jornada 3'!D$11:D$14,MATCH(2,'Jornada 3'!E$11:E$14,0)),INDEX('Jornada 3'!D$4:D$7,MATCH(4,'Jornada 3'!E$4:E$7,0))) -> ELISA CAROLINA DIAZ LAGUNA | E12: =COUNTIF(C$11:C$14,">"&C12)+COUNTIF($C$11:C12,C12) -> 2 | F12: =D12 -> ELISA CAROLINA DIAZ LAGUNA | H12: =D14 -> ALONSO CISNEROS SANCHEZ | J12: =D13 -> JESUS ANTONIO SEPULVEDA RODRIGUEZ | L12: =D14 -> ALONSO CISNEROS SANCHEZ | N12: =D14 -> ALONSO CISNEROS SANCHEZ | P12: =D13 -> JESUS ANTONIO SEPULVEDA RODRIGUEZ | S12: =COUNTIF(T$4:T$27,">"&T12)+1 -> 1 | T12: =$C$41 -> 0 | U12: =$D$41 -> ADRIANA ESPINOZA SALDAÑA
C13: =(H13-F13)+(J13-L13)+(P13-N13) -> 0 | D13: =IF('Jornada 3'!G$70=1,INDEX('Jornada 3'!D$11:D$14,MATCH(3,'Jornada 3'!E$11:E$14,0)),INDEX('Jornada 3'!D$18:D$21,MATCH(1,'Jornada 3'!E$18:E$21,0))) -> JESUS ANTONIO SEPULVEDA RODRIGUEZ | E13: =COUNTIF(C$11:C$14,">"&C13)+COUNTIF($C$11:C13,C13) -> 3 | S13: =COUNTIF(T$4:T$27,">"&T13)+1 -> 1 | T13: =$C$33 -> 0 | U13: =$D$33 -> ESTEFANO ROLANDO BECERRA HERNANDEZ
C14: =(H13-F13)+(L13-J13)+(N13-P13) -> 0 | D14: =IF('Jornada 3'!G$70=1,INDEX('Jornada 3'!D$18:D$21,MATCH(1,'Jornada 3'!E$18:E$21,0)),INDEX('Jornada 3'!D$18:D$21,MATCH(2,'Jornada 3'!E$18:E$21,0))) -> ALONSO CISNEROS SANCHEZ | E14: =COUNTIF(C$11:C$14,">"&C14)+COUNTIF($C$11:C14,C14) -> 4 | S14: =COUNTIF(T$4:T$27,">"&T14)+1 -> 1 | T14: =$C$20 -> 0 | U14: =$D$20 -> EMILIO MATEO OLIVARES CORTÉS
S15: =COUNTIF(T$4:T$27,">"&T15)+1 -> 1 | T15: =$C$12 -> 0 | U15: =$D$12 -> ELISA CAROLINA DIAZ LAGUNA
S16: =COUNTIF(T$4:T$27,">"&T16)+1 -> 1 | T16: =$C$27 -> 0 | U16: =$D$27 -> CAMILO RODRIGUEZ PACHECO
B17: Cancha 3 18:00 HS | C17: Puntos | D17: Jugadores | F17: Set 1 | J17: Set 2 | N17: Set 3 | S17: =COUNTIF(T$4:T$27,">"&T17)+1 -> 1 | T17: =$C$5 -> 0 | U17: =$D$5 -> MARIANO GOMEZ VUILLEUMIER
C18: =(F20-H20)+(J20-L20)+(N20-P20) -> 0 | D18: =IF('Jornada 3'!G$70=1,INDEX('Jornada 3'!D$11:D$14,MATCH(4,'Jornada 3'!E$11:E$14,0)),INDEX('Jornada 3'!D$11:D$14,MATCH(3,'Jornada 3'!E$11:E$14,0))) -> IKER FRANCISCO NORIEGA JIMENEZ | E18: =COUNTIF(C$18:C$21,">"&C18)+COUNTIF($C$18:C18,C18) -> 1 | F18: =D18 -> IKER FRANCISCO NORIEGA JIMENEZ | G18: VS | H18: =D20 -> EMILIO MATEO OLIVARES CORTÉS | J18: =D18 -> IKER FRANCISCO NORIEGA JIMENEZ | K18: VS | L18: =D19 -> DIEGO PATRICIO FERNANDEZ VIERA | N18: =D18 -> IKER FRANCISCO NORIEGA JIMENEZ | O18: VS | P18: =D19 -> DIEGO PATRICIO FERNANDEZ VIERA | S18: =COUNTIF(T$4:T$27,">"&T18)+1 -> 1 | T18: =$C$6 -> 0 | U18: =$D$6 -> NICOLAS MAXIMILIANO BRILL HERRERA
C19: =(F20-H20)+(L20-J20)+(P20-N20) -> 0 | D19: =IF('Jornada 3'!G$70=1,INDEX('Jornada 3'!D$18:D$21,MATCH(2,'Jornada 3'!E$18:E$21,0)),INDEX('Jornada 3'!D$11:D$14,MATCH(4,'Jornada 3'!E$11:E$14,0))) -> DIEGO PATRICIO FERNANDEZ VIERA | E19: =COUNTIF(C$18:C$21,">"&C19)+COUNTIF($C$18:C19,C19) -> 2 | F19: =D19 -> DIEGO PATRICIO FERNANDEZ VIERA | H19: =D21 -> MIGUEL ALCARAZ AMEZCUA | J19: =D20 -> EMILIO MATEO OLIVARES CORTÉS | L19: =D21 -> MIGUEL ALCARAZ AMEZCUA | N19: =D21 -> MIGUEL ALCARAZ AMEZCUA | P19: =D20 -> EMILIO MATEO OLIVARES CORTÉS | S19: =COUNTIF(T$4:T$27,">"&T19)+1 -> 1 | T19: =$C$14 -> 0 | U19: =$D$14 -> ALONSO CISNEROS SANCHEZ
C20: =(H20-F20)+(J20-L20)+(P20-N20) -> 0 | D20: =IF('Jornada 3'!G$70=1,INDEX('Jornada 3'!D$18:D$21,MATCH(3,'Jornada 3'!E$18:E$21,0)),INDEX('Jornada 3'!D$25:D$28,MATCH(1,'Jornada 3'!E$25:E$28,0))) -> EMILIO MATEO OLIVARES CORTÉS | E20: =COUNTIF(C$18:C$21,">"&C20)+COUNTIF($C$18:C20,C20) -> 3 | S20: =COUNTIF(T$4:T$27,">"&T20)+1 -> 1 | T20: =$C$26 -> 0 | U20: =$D$26 -> JOSE EMILIANO VAZQUEZ NUÑO
C21: =(H20-F20)+(L20-J20)+(N20-P20) -> 0 | D21: =IF('Jornada 3'!G$70=1,INDEX('Jornada 3'!D$25:D$28,MATCH(1,'Jornada 3'!E$25:E$28,0)),INDEX('Jornada 3'!D$25:D$28,MATCH(2,'Jornada 3'!E$25:E$28,0))) -> MIGUEL ALCARAZ AMEZCUA | E21: =COUNTIF(C$18:C$21,">"&C21)+COUNTIF($C$18:C21,C21) -> 4 | S21: =COUNTIF(T$4:T$27,">"&T21)+1 -> 1 | T21: =$C$19 -> 0 | U21: =$D$19 -> DIEGO PATRICIO FERNANDEZ VIERA
S22: =COUNTIF(T$4:T$27,">"&T22)+1 -> 1 | T22: =$C$21 -> 0 | U22: =$D$21 -> MIGUEL ALCARAZ AMEZCUA
S23: =COUNTIF(T$4:T$27,">"&T23)+1 -> 1 | T23: =$C$7 -> 0 | U23: =$D$7 -> MARIANO NAVARRO LEAÑO
B24: Cancha 4 17:00 HS | C24: Puntos | D24: Jugadores | F24: Set 1 | J24: Set 2 | N24: Set 3 | S24: =COUNTIF(T$4:T$27,">"&T24)+1 -> 1 | T24: =$C$13 -> 0 | U24: =$D$13 -> JESUS ANTONIO SEPULVEDA RODRIGUEZ
C25: =(F27-H27)+(J27-L27)+(N27-P27) -> 0 | D25: =IF('Jornada 3'!G$70=1,INDEX('Jornada 3'!D$18:D$21,MATCH(4,'Jornada 3'!E$18:E$21,0)),INDEX('Jornada 3'!D$18:D$21,MATCH(3,'Jornada 3'!E$18:E$21,0))) -> MAURICIO LOZANO CASTILLERO | E25: =COUNTIF(C$25:C$28,">"&C25)+COUNTIF($C$25:C25,C25) -> 1 | F25: =D25 -> MAURICIO LOZANO CASTILLERO | G25: VS | H25: =D27 -> CAMILO RODRIGUEZ PACHECO | J25: =D25 -> MAURICIO LOZANO CASTILLERO | K25: VS | L25: =D26 -> JOSE EMILIANO VAZQUEZ NUÑO | N25: =D25 -> MAURICIO LOZANO CASTILLERO | O25: VS | P25: =D26 -> JOSE EMILIANO VAZQUEZ NUÑO | S25: =COUNTIF(T$4:T$27,">"&T25)+1 -> 1 | T25: =$C$25 -> 0 | U25: =$D$25 -> MAURICIO LOZANO CASTILLERO
